Workbook

Sheet Trial Balance
A1: Trial Balance
C4: TB1 | E4: TB2 | G4: Adj | I4: Mgt Accs
A5: Account | B5: Balance | C5: Debit | D5: Credit | E5: Debit | F5: Credit | G5: Debit | H5: Credit | I5: Debit | J5: Credit | K5: October | L5: Movement | M5: Category
I6: =G6+C6+E6 -> 0 | J6: =H6+D6+F6 -> 0 | L6: =I6-J6 -> 0 | M6: Fixed assets
I7: =G7+C7+E7 -> 0 | J7: =H7+D7+F7 -> 0 | L7: =I7-J7 -> 0 | M7: Fixed assets
I8: =G8+C8+E8 -> 0 | J8: =H8+D8+F8 -> 0 | L8: =I8-J8 -> 0 | M8: Fixed assets
I9: =G9+C9+E9 -> 0 | J9: =H9+D9+F9 -> 0 | L9: =I9-J9 -> 0 | M9: Fixed assets
I10: =G10+C10+E10 -> 0 | J10: =H10+D10+F10 -> 0 | L10: =I10-J10 -> 0 | M10: Fixed assets
I11: =G11+C11+E11 -> 0 | J11: =H11+D11+F11 -> 0 | L11: =I11-J11 -> 0 | M11: Fixed assets
I12: =G12+C12+E12 -> 0 | J12: =H12+D12+F12 -> 0 | L12: =I12-J12 -> 0 | M12: Fixed assets
I13: =G13+C13+E13 -> 0 | J13: =H13+D13+F13 -> 0 | L13: =I13-J13 -> 0 | M13: Fixed assets
I14: =G14+C14+E14 -> 0 | J14: =H14+D14+F14 -> 0 | L14: =I14-J14 -> 0 | M14: Fixed assets
I15: =G15+C15+E15 -> 0 | J15: =H15+D15+F15 -> 0 | L15: =I15-J15 -> 0 | M15: Intangible assets
I16: =G16+C16+E16 -> 0 | J16: =H16+D16+F16 -> 0 | L16: =I16-J16 -> 0 | M16: Intangible assets
I17: =G17+C17+E17 -> 0 | J17: =H17+D17+F17 -> 0 | L17: =I17-J17 -> 0 | M17: Stock
... I53: =G53+C53+E53 -> 0 | J53: =H53+D53+F53 -> 0 | L53: =I53-J53 -> 0 | M53: P&L
I54: =G54+C54+E54 -> 0 | J54: =H54+D54+F54 -> 0 | L54: =J54-I54-K54 -> 0 | M54: Sales
I55: =G55+C55+E55 -> 0 | J55: =H55+D55+F55 -> 0 | L55: =J55-I55-K55 -> 0 | M55: Sales
I56: =G56+C56+E56 -> 0 | J56: =H56+D56+F56 -> 0 | L56: =J56-I56-K56 -> 0 | M56: Sales
I57: =G57+C57+E57 -> 0 | J57: =H57+D57+F57 -> 0 | L57: =J57-I57-K57 -> 0 | M57: Sales
I58: =G58+C58+E58 -> 0 | J58: =H58+D58+F58 -> 0 | L58: =J58-I58-K58 -> 0 | M58: Sales
I59: =G59+C59+E59 -> 0 | J59: =H59+D59+F59 -> 0 | L59: =J59-I59-K59 -> 0 | M59: Sales
I60: =G60+C60+E60 -> 0 | J60: =H60+D60+F60 -> 0 | L60: =J60-I60-K60 -> 0 | M60: Sales
I61: =G61+C61+E61 -> 0 | J61: =H61+D61+F61 -> 0 | L61: =J61-I61-K61 -> 0 | M61: Sales
I62: =G62+C62+E62 -> 0 | J62: =H62+D62+F62 -> 0 | L62: =J62-I62-K62 -> 0 | M62: Sales
I63: =G63+C63+E63 -> 0 | J63: =H63+D63+F63 -> 0 | L63: =J63-I63-K63 -> 0 | M63: Sales
I64: =G64+C64+E64 -> 0 | J64: =H64+D64+F64 -> 0 | L64: =J64-I64-K64 -> 0 | M64: Direct
I65: =G65+C65+E65 -> 0 | J65: =H65+D65+F65 -> 0 | L65: =J65-I65-K65 -> 0 | M65: Direct
... I86: =G86+C86+E86 -> 0 | J86: =H86+D86+F86 -> 0 | L86: =J86-I86-K86 -> 0 | M86: G&A
I87: =G87+C87+E87 -> 0 | J87: =H87+D87+F87 -> 0 | L87: =J87-I87-K87 -> 0
I88: =G88+C88+E88 -> 0 | J88: =H88+D88+F88 -> 0 | L88: =J88-I88-K88 -> 0 | M88: Direct
I89: =G89+C89+E89 -> 0 | J89: =H89+D89+F89 -> 0 | L89: =J89-I89-K89 -> 0 | M89: Prod Indirect
I90: =G90+C90+E90 -> 0 | J90: =H90+D90+F90 -> 0 | L90: =J90-I90-K90 -> 0 | M90: R&D
I91: =G91+C91+E91 -> 0 | J91: =H91+D91+F91 -> 0 | L91: =J91-I91-K91 -> 0 | M91: S&M
I92: =G92+C92+E92 -> 0 | J92: =H92+D92+F92 -> 0 | L92: =J92-I92-K92 -> 0 | M92: G&A
I93: =G93+C93+E93 -> 0 | J93: =H93+D93+F93 -> 0 | L93: =J93-I93-K93 -> 0
I94: =G94+C94+E94 -> 0 | J94: =H94+D94+F94 -> 0 | L94: =J94-I94-K94 -> 0 | M94: Direct
I95: =G95+C95+E95 -> 0 | J95: =H95+D95+F95 -> 0 | L95: =J95-I95-K95 -> 0 | M95: Prod Indirect
I96: =G96+C96+E96 -> 0 | J96: =H96+D96+F96 -> 0 | L96: =J96-I96-K96 -> 0 | M96: R&D
I97: =G97+C97+E97 -> 0 | J97: =H97+D97+F97 -> 0 | L97: =J97-I97-K97 -> 0 | M97: S&M
...

Sheet TB 1

Sheet TB 2

Sheet Balance Sheet
H1: USD conversion | I1: 1.32 | M1: GBP
B3: Actual | C3: Budget | D3: Variance | G3: Actual | M3: Actual
A4: £'000 | B4: 45931 | C4: 45931 | D4: 45931 | G4: 45627 | M4: 45627
A6: Intangible Assets | B6: ='Trial Balance'!L15+'Trial Balance'!L16 -> 0 | D6: =-(C6-B6) -> 0 | I6: =G6-B6 -> 0
A7: Tangible Assets | D7: =-(C7-B7) -> 0 | G7: =19594*I1 -> 25864.08 | I7: =G7-B7 -> 25864.08 | M7: =19594 -> 19594
A8: Total Fixed Assets | C8: =SUM(C6:C7) -> 0 | D8: =SUM(D6:D7) -> 0 | G8: =SUM(G6:G7) -> 25864.08 | M8: =SUM(M6:M7) -> 19594
D10: =-(C10-B10) -> 0 | G10: 0 | I10: =G10-B10 -> 0 | M10: 0
A11: Trade Debtors | D11: =-(C11-B11) -> 0 | G11: =490043*I1 -> 646856.76 | I11: =G11-B11 -> 646856.76 | M11: =490043 -> 490043
A12: Other debtors | D12: =-(C12-B12) -> 0 | I12: =G12-B12 -> 0
A13: VAT | D13: =-(C13-B13) -> 0 | I13: =G13-B13 -> 0
A14: Cash | D14: =-(C14-B14) -> 0 | G14: =1633703*I1 -> 2156488 | I14: =G14-B14 -> 2156488 | M14: =1633703 -> 1633703
A15: Total Current Assets | B15: =SUM(B10:B14) -> 0 | C15: =SUM(C10:C14) -> 0 | D15: =SUM(D10:D14) -> 0 | G15: =SUM(G10:G14) -> 2803344.7 | M15: =SUM(M10:M14) -> 2123746
A17: Trade Creditors | D17: =-(C17-B17) -> 0 | G17: =(-334279+99000)*I1 -> -310568.28 | I17: =G17-B17 -> -310568.28 | M17: =(-334279+99000) -> -235279
A18: Deferred Tax | D18: =-(C18-B18) -> 0 | I18: =G18-B18 -> 0
A19: Other creditors | D19: =-(C19-B19) -> 0 | I19: =G19-B19 -> 0
A20: Total Current Liabilities | B20: =SUM(B17:B19) -> 0 | C20: =SUM(C17:C19) -> 0 | D20: =SUM(D17:D19) -> 0 | G20: =SUM(G17:G19) -> -310568.28 | M20: =SUM(M17:M19) -> -235279
A22: Loans | D22: =-(C22-B22) -> 0 | G22: =(-192000-99000)*I1 -> -384120 | I22: =G22-B22 -> -384120 | K22: =318000-(9000*3)+G22 -> -93120 | M22: =(-192000-99000) -> -291000
A24: Net Assets | B24: =B8+B15+B20+B22 -> 0 | C24: =C8+C15-C20-C22 -> 0 | D24: =D8+D15+D20+D22 -> 0 | G24: =G8+G15+G20+G22 -> 2134520.5 | M24: =M8+M15+M20+M22 -> 1617061
A26: Share Cap
A27: Share capital | D27: =-(C27-B27) -> 0 | G27: =168*I1 -> 221.76 | I27: =G27-B27 -> 221.76 | M27: =168 -> 168
A28: Share premium | D28: =-(C28-B28) -> 0 | G28: =7328854*I1 -> 9674087.3 | I28: =G28-B28 -> 9674087.3 | M28: =7328854 -> 7328854
A29: Other reserve | D29: =-(C29-B29) -> 0 | I29: =G29-B29 -> 0
A30: BFWD retained earnings | D30: =-(C30-B30) -> 0 | G30: =-5711961*I1 -> -7539788.5 | I30: =G30-B30 -> -7539788.5 | M30: =-5711961 -> -5711961
A31: 2025 P&L | D31: =-(C31-B31) -> 0 | I31: =G31-B31 -> 0 | J31: =I31+'P&L'!AL39 -> 0
B32: =SUM(B27:B31) -> 0 | C32: =SUM(C27:C31) -> 0 | D32: =SUM(D27:D31) -> 0 | G32: =SUM(G27:G31) -> 2134520.5 | M32: =SUM(M27:M31) -> 1617061
A34: Difference | B34: =B24-B32 -> 0 | C34: =C24-C32 -> 0 | D34: =D24-D32 -> 0 | G34: =G24-G32 -> 0 | M34: =M24-M32 -> 0

Sheet All In One
B1: Opening Balance Sheet | C1: Movement | D1: 45627 | E1: Movement | F1: 45931 | G1: Movement | H1: =F1+31 -> 45962 | I1: Movement | J1: =H1+31 -> 45993 | K1: Movement | L1: =J1+31 -> 46024 | M1: Movement | N1: =L1+31 -> 46055 | O1: Movement | P1: =N1+31 -> 46086 | Q1: Movement | R1: =P1+31 -> 46117 | S1: Movement | T1: =R1+31 -> 46148 | V1: =T1+31 -> 46179 | X1: =V1+31 -> 46210 | Z1: =X1+31 -> 46241 | AB1: =Z1+31 -> 46272 | AD1: =AB1+31 -> 46303 | AF1: =AD1+31 -> 46334 | AH1: =AF1+31 -> 46365 | AJ1: =AH1+31 -> 46396 | AL1: =AJ1+31 -> 46427 | AN1: =AL1+31 -> 46458 | AP1: =AN1+31 -> 46489 | AR1: =AP1+31 -> 46520 | AT1: =AR1+31 -> 46551 | AV1: =AT1+31 -> 46582 | AX1: =AV1+31 -> 46613 | AZ1: =AX1+31 -> 46644 | BB1: =AZ1+31 -> 46675 | BD1: =BB1+31 -> 46706 | BF1: =BD1+31 -> 46737 | BH1: =BF1+31 -> 46768 | BJ1: =BH1+31 -> 46799 | BL1: =BJ1+31 -> 46830 | BN1: =BL1+31 -> 46861 | BP1: =BN1+31 -> 46892 | BR1: =BP1+31 -> 46923 | BT1: =BR1+31 -> 46954 | BV1: =BT1+31 -> 46985 | BX1: =BV1+31 -> 47016 | BZ1: =BX1+31 -> 47047 | CB1: =BZ1+31 -> 47078 | CD1: =CB1+31 -> 47109 | CF1: =CD1+31 -> 47140 | CH1: =CF1+31 -> 47171 | CJ1: =CH1+31 -> 47202 | CL1: =CJ1+31 -> 47233 | CN1: =CL1+31 -> 47264 | CP1: =CN1+31 -> 47295 | CR1: =CP1+31 -> 47326 | CT1: =CR1+31 -> 47357 | CV1: =CT1+31 -> 47388 | CX1: =CV1+31 -> 47419 | CZ1: =CX1+31 -> 47450 | DB1: =CZ1+30 -> 47480 | DD1: =DB1+31 -> 47511 | DF1: =DD1+30 -> 47541 | DH1: =DF1+31 -> 47572 | DJ1: =DH1+31 -> 47603 | DL1: =DJ1+30 -> 47633 | DN1: =DL1+30 -> 47663 | DP1: =DN1+30 -> 47693 | DR1: =DP1+30 -> 47723 | DT1: =DR1+30 -> 47753 | DV1: =DT1+30 -> 47783 | DX1: =DV1+30 -> 47813 | DZ1: =DX1+30 -> 47843 | EB1: =DZ1+30 -> 47873 | ED1: =EB1+30 -> 47903 | EF1: =ED1+30 -> 47933 | EH1: =EF1+30 -> 47963 | EJ1: =EH1+30 -> 47993 | EL1: =EJ1+30 -> 48023 | EN1: =EL1+30 -> 48053 | EP1: =EN1+30 -> 48083 | ER1: =EP1+30 -> 48113 | ET1: =ER1+30 -> 48143 | EV1: =ET1+30 -> 48173 | EX1: =EV1+30 -> 48203
A2: £'000
A4: Cash | B4: ='Balance Sheet'!G14 -> 2156488 | D4: =B4 -> 2156488 | F4: =D4+SUM(E6:E66) -> 1379580.2 | H4: =F4+SUM(G6:G66) -> 1145722.3 | J4: =H4+SUM(I6:I66) -> 1114771.9 | L4: =J4+SUM(K6:K65) -> 525369.07 | N4: =L4+SUM(M6:M65) -> 234504.52 | P4: =N4+SUM(O6:O65) -> 386849.97 | R4: =P4+SUM(Q6:Q65) -> 218691.12 | T4: =R4+SUM(S6:S66) -> -113381.73 | V4: =T4+SUM(U6:U66) -> -348684.37 | X4: =V4+SUM(W6:W66) -> -615345.67 | Z4: =X4+SUM(Y6:Y66) -> -873574.97 | AB4: =Z4+SUM(AA6:AA66) -> -1076995.3 | AD4: =AB4+SUM(AC6:AC66) -> -1235968.2 | AF4: =AD4+SUM(AE6:AE66) -> -1451911 | AH4: =AF4+SUM(AG6:AG66) -> -1552403.9 | AJ4: =AH4+SUM(AI6:AI66) -> -1730071.2 | AL4: =AJ4+SUM(AK6:AK66) -> -1906464.3 | AN4: =AL4+SUM(AM6:AM66) -> -2248839.1 | AP4: =AN4+SUM(AO6:AO66) -> -2411916.9 | AR4: =AP4+SUM(AQ6:AQ66) -> -2859590.1 | AT4: =AR4+SUM(AS6:AS66) -> -3366634.3 | AV4: =AT4+SUM(AU6:AU66) -> -3716325 | AX4: =AV4+SUM(AW6:AW66) -> -4040136.2 | AZ4: =AX4+SUM(AY6:AY66) -> -4291009.4 | BB4: =AZ4+SUM(BA6:BA66) -> -4488851.4 | BD4: =BB4+SUM(BC6:BC66) -> -4696615.9 | BF4: =BD4+SUM(BE6:BE66) -> -4881477.8 | BH4: =BF4+SUM(BG6:BG66) -> -5078815.3 | BJ4: =BH4+SUM(BI6:BI66) -> -5127625.5 | BL4: =BJ4+SUM(BK6:BK66) -> -5328038.9 | BN4: =BL4+SUM(BM6:BM66) -> -5289155 | BP4: =BN4+SUM(BO6:BO66) -> -5228321.3 | BR4: =BP4+SUM(BQ6:BQ66) -> -5416360.7 | BT4: =BR4+SUM(BS6:BS66) -> -5499948.4 | BV4: =BT4+SUM(BU6:BU66) -> -5503661 | BX4: =BV4+SUM(BW6:BW66) -> -5417218.7 | BZ4: =BX4+SUM(BY6:BY66) -> -5427463.8 | CB4: =BZ4+SUM(CA6:CA66) -> -5364459 | CD4: =CB4+SUM(CC6:CC66) -> -5216933.3 | CF4: =CD4+SUM(CE6:CE66) -> -4689759.4 | CH4: =CF4+SUM(CG6:CG66) -> -4220448.3 | CJ4: =CH4+SUM(CI6:CI66) -> -3827594.7 | CL4: =CJ4+SUM(CK6:CK66) -> -3349243.1 | CN4: =CL4+SUM(CM6:CM66) -> -2647637.4 | CP4: =CN4+SUM(CO6:CO66) -> -1638331.7 | CR4: =CP4+SUM(CQ6:CQ66) -> -767316.79 | CT4: =CR4+SUM(CS6:CS66) -> 228583.95 | CV4: =CT4+SUM(CU6:CU66) -> 1347709.7 | CX4: =CV4+SUM(CW6:CW66) -> 2709668.8 | CZ4: =CX4+SUM(CY6:CY66) -> 3976815.3 | DB4: =CZ4+SUM(DA6:DA66) -> 5474170.2 | DD4: =DB4+SUM(DC6:DC66) -> 7401074.8 | DF4: =DD4+SUM(DE6:DE66) -> 9685340.5 | DH4: =DF4+SUM(DG6:DG66) -> 12032523 | DJ4: =DH4+SUM(DI6:DI66) -> 14243764 | DL4: =DJ4+SUM(DK6:DK66) -> 16725176 | DN4: =DL4+SUM(DM6:DM66) -> 19446059 | DP4: =DN4+SUM(DO6:DO66) -> 22254983 | DR4: =DP4+SUM(DQ6:DQ66) -> 25240270 | DT4: =DR4+SUM(DS6:DS66) -> 28607699 | DV4: =DT4+SUM(DU6:DU66) -> 32359149 | DX4: =DV4+SUM(DW6:DW66) -> 36159952 | DZ4: =DX4+SUM(DY6:DY66) -> 40284131 | EB4: =DZ4+SUM(EA6:EA66) -> 44993139 | ED4: =EB4+SUM(EC6:EC66) -> 50055776 | EF4: =ED4+SUM(EE6:EE66) -> 55022475 | EH4: =EF4+SUM(EG6:EG66) -> 60138050 | EJ4: =EH4+SUM(EI6:EI66) -> 65713552 | EL4: =EJ4+SUM(EK6:EK66) -> 71415918 | EN4: =EL4+SUM(EM6:EM66) -> 77136493 | EP4: =EN4+SUM(EO6:EO66) -> 83240484 | ER4: =EP4+SUM(EQ6:EQ66) -> 89851475 | ET4: =ER4+SUM(ES6:ES66) -> 96384695 | EV4: =ET4+SUM(EU6:EU66) -> 1.0308733e+08 | EX4: =EV4+SUM(EW6:EW66) -> 1.1010514e+08
A6: Intangible Assets | B6: ='Balance Sheet'!G6 -> 0 | D6: =B6 -> 0 | E6: =D6-F6 -> 0 | F6: =Budgets!D67 -> 0 | G6: =F6-H6 -> 0 | H6: =Budgets!E67 -> 0 | I6: =H6-J6 -> 0 | J6: =Budgets!F67 -> 0 | K6: =J6-L6 -> 0 | L6: =Budgets!G67 -> 0 | M6: =L6-N6 -> 0 | N6: =Budgets!H67 -> 0 | O6: =N6-P6 -> 0 | P6: =Budgets!I67 -> 0 | Q6: =P6-R6 -> 0 | R6: =Budgets!J67 -> 0 | S6: =R6-T6 -> 0 | T6: =Budgets!K67 -> 0 | U6: =T6-V6 -> 0 | V6: =Budgets!L67 -> 0 | W6: =V6-X6 -> 0 | X6: =Budgets!M67 -> 0 | Y6: =X6-Z6 -> 0 | Z6: =Budgets!N67 -> 0 | AA6: =Z6-AB6 -> 0 | AB6: =Budgets!O67 -> 0 | AC6: =AB6-AD6 -> 0 | AD6: =Budgets!P67 -> 0 | AE6: =AD6-AF6 -> 0 | AF6: =Budgets!Q67 -> 0 | AG6: =AF6-AH6 -> 0 | AH6: =Budgets!R67 -> 0 | AI6: =AH6-AJ6 -> 0 | AJ6: =Budgets!S67 -> 0 | AK6: =AJ6-AL6 -> 0 | AL6: =Budgets!T67 -> 0 | AM6: =AL6-AN6 -> 0 | AN6: =Budgets!U67 -> 0 | AO6: =AN6-AP6 -> 0 | AP6: =Budgets!V67 -> 0 | AQ6: =AP6-AR6 -> 0 | AR6: =Budgets!W67 -> 0 | AS6: =AR6-AT6 -> 0 | AT6: =Budgets!X67 -> 0 | AU6: =AT6-AV6 -> 0 | AV6: =Budgets!Y67 -> 0 | AW6: =AV6-AX6 -> 0 | AX6: =Budgets!Z67 -> 0 | AY6: =AX6-AZ6 -> 0 | AZ6: =Budgets!AA67 -> 0 | BA6: =AZ6-AH6 -> 0 | BB6: =Budgets!AB67 -> 0 | BC6: =AH6-BD6 -> 0 | BD6: =Budgets!AC67 -> 0 | BE6: =BD6-BF6 -> 0 | BF6: =Budgets!AD67 -> 0 | BG6: =BF6-BH6 -> 0 | BH6: =Budgets!AE67 -> 0 | BI6: =BH6-BJ6 -> 0 | BJ6: =Budgets!AF67 -> 0 | BK6: =BJ6-BL6 -> 0 | BL6: =Budgets!AG67 -> 0 | BM6: =BL6-BN6 -> 0 | BN6: =Budgets!AH67 -> 0 | BO6: =BN6-BP6 -> 0 | BP6: =Budgets!AI67 -> 0 | BQ6: =BP6-BR6 -> 0 | BR6: =Budgets!AJ67 -> 0 | BS6: =BR6-BT6 -> 0 | BT6: =Budgets!AK67 -> 0 | BU6: =BT6-BV6 -> 0 | BV6: =Budgets!AL67 -> 0 | BW6: =BV6-BX6 -> 0 | BX6: =Budgets!AM67 -> 0 | BY6: =BX6-BZ6 -> 0 | BZ6: =Budgets!AN67 -> 0 | CA6: =BZ6-CB6 -> 0 | CB6: =Budgets!AO67 -> 0 | CC6: =CB6-CD6 -> 0 | CD6: =Budgets!AP67 -> 0 | CE6: =CD6-CF6 -> 0 | CF6: =Budgets!AQ67 -> 0 | CG6: =CF6-CH6 -> 0 | CH6: =Budgets!AR67 -> 0 | CI6: =CH6-CJ6 -> 0 | CJ6: =Budgets!AS67 -> 0 | CK6: =CJ6-CL6 -> 0 | CL6: =Budgets!AT67 -> 0 | CM6: =CL6-CN6 -> 0 | CN6: =Budgets!AU67 -> 0 | CO6: =CN6-CP6 -> 0 | CP6: =Budgets!AV67 -> 0 | CQ6: =CP6-CR6 -> 0 | CR6: =Budgets!AW67 -> 0 | CS6: =CR6-CT6 -> 0 | CT6: =Budgets!AX67 -> 0 | CU6: =CT6-CV6 -> 0 | CV6: =Budgets!AY67 -> 0 | CW6: =CV6-CX6 -> 0 | CX6: =Budgets!AZ67 -> 0 | CY6: =CX6-CZ6 -> 0 | CZ6: =Budgets!BA67 -> 0 | DA6: =CZ6-DB6 -> 0 | DB6: =Budgets!BB67 -> 0 | DC6: =DB6-DD6 -> 0 | DD6: =Budgets!BC67 -> 0 | DE6: =DD6-DF6 -> 0 | DF6: =Budgets!BD67 -> 0 | DG6: =DF6-DH6 -> 0 | DH6: =Budgets!BE67 -> 0 | DI6: =DH6-DJ6 -> 0 | DJ6: =Budgets!BF67 -> 0 | DK6: =DJ6-DL6 -> 0 | DL6: =Budgets!BG67 -> 0 | DM6: =DL6-DN6 -> 0 | DN6: =Budgets!BH67 -> 0 | DO6: =DN6-DP6 -> 0 | DP6: =Budgets!BI67 -> 0 | DQ6: =DP6-DR6 -> 0 | DR6: =Budgets!BJ67 -> 0 | DS6: =DR6-DT6 -> 0 | DT6: =Budgets!BK67 -> 0 | DU6: =DT6-DV6 -> 0 | DV6: =Budgets!BL67 -> 0 | DW6: =DV6-DX6 -> 0 | DX6: =Budgets!BM67 -> 0 | DY6: =DX6-DZ6 -> 0 | DZ6: =Budgets!BN67 -> 0 | EA6: =DZ6-EB6 -> 0 | EB6: =Budgets!BO67 -> 0 | EC6: =EB6-ED6 -> 0 | ED6: =Budgets!BP67 -> 0 | EE6: =ED6-EF6 -> 0 | EF6: =Budgets!BQ67 -> 0 | EG6: =EF6-EH6 -> 0 | EH6: =Budgets!BR67 -> 0 | EI6: =EH6-EJ6 -> 0 | EJ6: =Budgets!BS67 -> 0 | EK6: =EJ6-EL6 -> 0 | EL6: =Budgets!BT67 -> 0 | EM6: =EL6-EN6 -> 0 | EN6: =Budgets!BU67 -> 0 | EO6: =EN6-EP6 -> 0 | EP6: =Budgets!BV67 -> 0 | EQ6: =EP6-ER6 -> 0 | ER6: =Budgets!BW67 -> 0 | ES6: =ER6-ET6 -> 0 | ET6: =Budgets!BX67 -> 0 | EU6: =ET6-EV6 -> 0 | EV6: =Budgets!BY67 -> 0 | EW6: =EV6-EX6 -> 0 | EX6: =Budgets!BZ67 -> 0
A7: Tangible Assets | B7: ='Balance Sheet'!G7 -> 25864.08 | D7: =B7 -> 25864.08 | E7: =D7-F7 -> -19109.64 | F7: =Budgets!D68 -> 44973.72 | G7: =F7-H7 -> -661.16 | H7: =Budgets!E68 -> 45634.88 | I7: =H7-J7 -> 0 | J7: =Budgets!F68 -> 45634.88 | K7: =J7-L7 -> -1226.095 | L7: =Budgets!G68 -> 46860.975 | M7: =L7-N7 -> 2873.905 | N7: =Budgets!H68 -> 43987.07 | O7: =N7-P7 -> 3373.905 | P7: =Budgets!I68 -> 40613.165 | Q7: =P7-R7 -> 3873.905 | R7: =Budgets!J68 -> 36739.26 | S7: =R7-T7 -> 3873.905 | T7: =Budgets!K68 -> 32865.355 | U7: =T7-V7 -> 3873.905 | V7: =Budgets!L68 -> 28991.45 | W7: =V7-X7 -> 3873.905 | X7: =Budgets!M68 -> 25117.545 | Y7: =X7-Z7 -> 3873.905 | Z7: =Budgets!N68 -> 21243.64 | AA7: =Z7-AB7 -> 3873.905 | AB7: =Budgets!O68 -> 17369.735 | AC7: =AB7-AD7 -> 3873.905 | AD7: =Budgets!P68 -> 13495.83 | AE7: =AD7-AF7 -> 3873.905 | AF7: =Budgets!Q68 -> 9621.925 | AG7: =AF7-AH7 -> 3873.905 | AH7: =Budgets!R68 -> 5748.02 | AI7: =AH7-AJ7 -> 5123.905 | AJ7: =Budgets!S68 -> 624.115 | AK7: =AJ7-AL7 -> 5540.5717 | AL7: =Budgets!T68 -> -4916.4567 | AM7: =AL7-AN7 -> 5957.2383 | AN7: =Budgets!U68 -> -10873.695 | AO7: =AN7-AP7 -> -118626.1 | AP7: =Budgets!V68 -> 107752.4 | AQ7: =AP7-AR7 -> 1790.5717 | AR7: =Budgets!W68 -> 105961.83 | AS7: =AR7-AT7 -> -7376.095 | AT7: =Budgets!X68 -> 113337.92 | AU7: =AT7-AV7 -> 3040.5717 | AV7: =Budgets!Y68 -> 110297.35 | AW7: =AV7-AX7 -> 13040.572 | AX7: =Budgets!Z68 -> 97256.78 | AY7: =AX7-AZ7 -> 3457.2383 | AZ7: =Budgets!AA68 -> 93799.542 | BA7: =AZ7-BB7 -> 3873.905 | BB7: =Budgets!AB68 -> 89925.637 | BC7: =BB7-BD7 -> 13873.905 | BD7: =Budgets!AC68 -> 76051.732 | BE7: =BD7-BF7 -> 13873.905 | BF7: =Budgets!AD68 -> 62177.827 | BG7: =BF7-BH7 -> -7666.6667 | BH7: =Budgets!AE68 -> 69844.493 | BI7: =BH7-BJ7 -> 2250 | BJ7: =Budgets!AF68 -> 67594.493 | BK7: =BJ7-BL7 -> 2166.6667 | BL7: =Budgets!AG68 -> 65427.827 | BM7: =BL7-BN7 -> -7500 | BN7: =Budgets!AH68 -> 72927.827 | BO7: =BN7-BP7 -> 2916.6667 | BP7: =Budgets!AI68 -> 70011.16 | BQ7: =BP7-BR7 -> 3333.3333 | BR7: =Budgets!AJ68 -> 66677.827 | BS7: =BR7-BT7 -> 3750 | BT7: =Budgets!AK68 -> 62927.827 | BU7: =BT7-BV7 -> 4166.6667 | BV7: =Budgets!AL68 -> 58761.16 | BW7: =BV7-BX7 -> 4583.3333 | BX7: =Budgets!AM68 -> 54177.827 | BY7: =BX7-BZ7 -> -100416.67 | BZ7: =Budgets!AN68 -> 154594.49 | CA7: =BZ7-CB7 -> -47500 | CB7: =Budgets!AO68 -> 202094.49 | CC7: =CB7-CD7 -> 22500 | CD7: =Budgets!AP68 -> 179594.49 | CE7: =CD7-CF7 -> -103333.33 | CF7: =Budgets!AQ68 -> 282927.83 | CG7: =CF7-CH7 -> -21666.667 | CH7: =Budgets!AR68 -> 304594.49 | CI7: =CH7-CJ7 -> -77500 | CJ7: =Budgets!AS68 -> 382094.49 | CK7: =CJ7-CL7 -> -1666.6667 | CL7: =Budgets!AT68 -> 383761.16 | CM7: =CL7-CN7 -> 16416.667 | CN7: =Budgets!AU68 -> 367344.49 | CO7: =CN7-CP7 -> 16083.333 | CP7: =Budgets!AV68 -> 351261.16 | CQ7: =CP7-CR7 -> 16166.667 | CR7: =Budgets!AW68 -> 335094.49 | CS7: =CR7-CT7 -> 16666.667 | CT7: =Budgets!AX68 -> 318427.83 | CU7: =CT7-CV7 -> 28250 | CV7: =Budgets!AY68 -> 290177.83 | CW7: =CV7-CX7 -> 27833.333 | CX7: =Budgets!AZ68 -> 262344.49 | CY7: =CX7-CZ7 -> 27833.333 | CZ7: =Budgets!BA68 -> 234511.16 | DA7: =CZ7-DB7 -> 27833.333 | DB7: =Budgets!BB68 -> 206677.83 | DC7: =DB7-DD7 -> 27000 | DD7: =Budgets!BC68 -> 179677.83 | DE7: =DD7-DF7 -> 26583.333 | DF7: =Budgets!BD68 -> 153094.49 | DG7: =DF7-DH7 -> 26166.667 | DH7: =Budgets!BE68 -> 126927.83 | DI7: =DH7-DJ7 -> 25333.333 | DJ7: =Budgets!BF68 -> 101594.49 | DK7: =DJ7-DL7 -> -3833.3333 | DL7: =Budgets!BG68 -> 105427.83 | DM7: =DL7-DN7 -> 16166.667 | DN7: =Budgets!BH68 -> 89261.16 | DO7: =DN7-DP7 -> 16166.667 | DP7: =Budgets!BI68 -> 73094.493 | DQ7: =DP7-DR7 -> -98833.333 | DR7: =Budgets!BJ68 -> 171927.83 | DS7: =DR7-DT7 -> 21166.667 | DT7: =Budgets!BK68 -> 150761.16 | DU7: =DT7-DV7 -> 7000 | DV7: =Budgets!BL68 -> 143761.16 | DW7: =DV7-DX7 -> 14500 | DX7: =Budgets!BM68 -> 129261.16 | DY7: =DX7-DZ7 -> 24500 | DZ7: =Budgets!BN68 -> 104761.16 | EA7: =DZ7-EB7 -> 24500 | EB7: =Budgets!BO68 -> 80261.16 | EC7: =EB7-ED7 -> 24500 | ED7: =Budgets!BP68 -> 55761.16 | EE7: =ED7-EF7 -> 24500 | EF7: =Budgets!BQ68 -> 31261.16 | EG7: =EF7-EH7 -> 24500 | EH7: =Budgets!BR68 -> 6761.16 | EI7: =EH7-EJ7 -> 6761.16 | EJ7: =Budgets!BS68 -> 0 | EK7: =EJ7-EL7 -> 0 | EL7: =Budgets!BT68 -> 0 | EM7: =EL7-EN7 -> 0 | EN7: =Budgets!BU68 -> 0 | EO7: =EN7-EP7 -> 0 | EP7: =Budgets!BV68 -> 0 | EQ7: =EP7-ER7 -> 0 | ER7: =Budgets!BW68 -> 0 | ES7: =ER7-ET7 -> 0 | ET7: =Budgets!BX68 -> 0 | EU7: =ET7-EV7 -> 0 | EV7: =Budgets!BY68 -> 0 | EW7: =EV7-EX7 -> 0 | EX7: =Budgets!BZ68 -> 0
A8: Total Fixed Assets | B8: =SUM(B6:B7) -> 25864.08 | D8: =SUM(D6:D7) -> 25864.08 | F8: =SUM(F6:F7) -> 44973.72 | H8: =SUM(H6:H7) -> 45634.88 | J8: =SUM(H6:H7) -> 45634.88 | L8: =SUM(L6:L7) -> 46860.975 | N8: =SUM(N6:N7) -> 43987.07 | P8: =SUM(P6:P7) -> 40613.165 | R8: =SUM(R6:R7) -> 36739.26 | T8: =SUM(T6:T7) -> 32865.355 | V8: =SUM(V6:V7) -> 28991.45 | X8: =SUM(X6:X7) -> 25117.545 | Z8: =SUM(Z6:Z7) -> 21243.64 | AB8: =SUM(AB6:AB7) -> 17369.735 | AD8: =SUM(AD6:AD7) -> 13495.83 | AF8: =SUM(AF6:AF7) -> 9621.925 | AH8: =SUM(AH6:AH7) -> 5748.02 | AJ8: =SUM(AJ6:AJ7) -> 624.115 | AL8: =SUM(AL6:AL7) -> -4916.4567 | AN8: =SUM(AN6:AN7) -> -10873.695 | AP8: =SUM(AP6:AP7) -> 107752.4 | AR8: =SUM(AR6:AR7) -> 105961.83 | AT8: =SUM(AT6:AT7) -> 113337.92 | AV8: =SUM(AV6:AV7) -> 110297.35 | AX8: =SUM(AX6:AX7) -> 97256.78 | AZ8: =SUM(AZ6:AZ7) -> 93799.542 | BB8: =SUM(BB6:BB7) -> 89925.637 | BD8: =SUM(BD6:BD7) -> 76051.732 | BF8: =SUM(BF6:BF7) -> 62177.827 | BH8: =SUM(BH6:BH7) -> 69844.493 | BJ8: =SUM(BJ6:BJ7) -> 67594.493 | BL8: =SUM(BL6:BL7) -> 65427.827 | BN8: =SUM(BN6:BN7) -> 72927.827 | BP8: =SUM(BP6:BP7) -> 70011.16 | BR8: =SUM(BR6:BR7) -> 66677.827 | BT8: =SUM(BT6:BT7) -> 62927.827 | BV8: =SUM(BV6:BV7) -> 58761.16 | BX8: =SUM(BX6:BX7) -> 54177.827 | BZ8: =SUM(BZ6:BZ7) -> 154594.49 | CB8: =SUM(CB6:CB7) -> 202094.49 | CD8: =SUM(CD6:CD7) -> 179594.49 | CF8: =SUM(CF6:CF7) -> 282927.83 | CH8: =SUM(CH6:CH7) -> 304594.49 | CJ8: =SUM(CJ6:CJ7) -> 382094.49 | CL8: =SUM(CL6:CL7) -> 383761.16 | CN8: =SUM(CN6:CN7) -> 367344.49 | CP8: =SUM(CP6:CP7) -> 351261.16 | CR8: =SUM(CR6:CR7) -> 335094.49 | CT8: =SUM(CT6:CT7) -> 318427.83 | CV8: =SUM(CV6:CV7) -> 290177.83 | CX8: =SUM(CX6:CX7) -> 262344.49 | CZ8: =SUM(CZ6:CZ7) -> 234511.16 | DB8: =SUM(DB6:DB7) -> 206677.83 | DD8: =SUM(DD6:DD7) -> 179677.83 | DF8: =SUM(DF6:DF7) -> 153094.49 | DH8: =SUM(DH6:DH7) -> 126927.83 | DJ8: =SUM(DJ6:DJ7) -> 101594.49 | DL8: =SUM(DL6:DL7) -> 105427.83 | DN8: =SUM(DN6:DN7) -> 89261.16 | DP8: =SUM(DP6:DP7) -> 73094.493 | DR8: =SUM(DR6:DR7) -> 171927.83 | DT8: =SUM(DT6:DT7) -> 150761.16 | DV8: =SUM(DV6:DV7) -> 143761.16 | DX8: =SUM(DX6:DX7) -> 129261.16 | DZ8: =SUM(DZ6:DZ7) -> 104761.16 | EB8: =SUM(EB6:EB7) -> 80261.16 | ED8: =SUM(ED6:ED7) -> 55761.16 | EF8: =SUM(EF6:EF7) -> 31261.16 | EH8: =SUM(EH6:EH7) -> 6761.16 | EJ8: =SUM(EJ6:EJ7) -> 0 | EL8: =SUM(EL6:EL7) -> 0 | EN8: =SUM(EN6:EN7) -> 0 | EP8: =SUM(EP6:EP7) -> 0 | ER8: =SUM(ER6:ER7) -> 0 | ET8: =SUM(ET6:ET7) -> 0 | EV8: =SUM(EV6:EV7) -> 0 | EX8: =SUM(EX6:EX7) -> 0
B10: ='Balance Sheet'!G10 -> 0 | D10: =B10 -> 0 | F10: =Budgets!D71 -> 0 | H10: =Budgets!E71 -> 0 | J10: =Budgets!F71 -> 0 | L10: =Budgets!G71 -> 0 | N10: =Budgets!H71 -> 0 | P10: =Budgets!I71 -> 0 | Q10: =P10-R10 -> 0 | R10: =Budgets!J71 -> 0 | S10: =R10-T10 -> 0 | T10: =Budgets!K71 -> 0 | U10: =T10-V10 -> 0 | V10: =Budgets!L71 -> 0 | W10: =V10-X10 -> 0 | X10: =Budgets!M71 -> 0 | Y10: =X10-Z10 -> 0 | Z10: =Budgets!N71 -> 0 | AA10: =Z10-AB10 -> 0 | AB10: =Budgets!O71 -> 0 | AC10: =AB10-AD10 -> 0 | AD10: =Budgets!P71 -> 0 | AE10: =AD10-AF10 -> 0 | AF10: =Budgets!Q71 -> 0 | AG10: =AF10-AH10 -> 0 | AH10: =Budgets!R71 -> 0 | AI10: =AH10-AJ10 -> 0 | AJ10: =Budgets!S71 -> 0 | AK10: =AJ10-AL10 -> 0 | AL10: =Budgets!T71 -> 0 | AM10: =AL10-AN10 -> 0 | AN10: =Budgets!U71 -> 0 | AO10: =AN10-AP10 -> 0 | AP10: =Budgets!V71 -> 0 | AQ10: =AP10-AR10 -> 0 | AR10: =Budgets!W71 -> 0 | AS10: =AR10-AT10 -> 0 | AT10: =Budgets!X71 -> 0 | AU10: =AT10-AV10 -> 0 | AV10: =Budgets!Y71 -> 0 | AW10: =AV10-AX10 -> 0 | AX10: =Budgets!Z71 -> 0 | AY10: =AX10-AZ10 -> 0 | AZ10: =Budgets!AA71 -> 0 | BA10: =AZ10-BB10 -> 0 | BB10: =Budgets!AB71 -> 0 | BC10: =BB10-BD10 -> 0 | BD10: =Budgets!AC71 -> 0 | BE10: =BD10-BF10 -> 0 | BF10: =Budgets!AD71 -> 0 | BG10: =BF10-BH10 -> 0 | BH10: =Budgets!AE71 -> 0 | BI10: =BH10-BJ10 -> 0 | BJ10: =Budgets!AF71 -> 0 | BK10: =BJ10-BL10 -> 0 | BL10: =Budgets!AG71 -> 0 | BM10: =BL10-BN10 -> 0 | BN10: =Budgets!AH71 -> 0 | BO10: =BN10-BP10 -> 0 | BP10: =Budgets!AI71 -> 0 | BQ10: =BP10-BR10 -> 0 | BR10: =Budgets!AJ71 -> 0 | BS10: =BR10-BT10 -> 0 | BT10: =Budgets!AK71 -> 0 | BU10: =BT10-BV10 -> 0 | BV10: =Budgets!AL71 -> 0 | BW10: =BV10-BX10 -> 0 | BX10: =Budgets!AM71 -> 0 | BY10: =BX10-BZ10 -> 0 | BZ10: =Budgets!AN71 -> 0 | CA10: =BZ10-BO10 -> 0 | CB10: =Budgets!AO71 -> 0 | CC10: =CB10-BQ10 -> 0 | CD10: =Budgets!AP71 -> 0 | CE10: =CD10-CF10 -> 0 | CF10: =Budgets!AQ71 -> 0 | CG10: =CF10-CH10 -> 0 | CH10: =Budgets!AR71 -> 0 | CI10: =CH10-CJ10 -> 0 | CJ10: =Budgets!AS71 -> 0 | CK10: =CJ10-CL10 -> 0 | CL10: =Budgets!AT71 -> 0 | CM10: =CL10-CN10 -> 0 | CN10: =Budgets!AU71 -> 0 | CO10: =CN10-CP10 -> 0 | CP10: =Budgets!AV71 -> 0 | CQ10: =CP10-CR10 -> 0 | CR10: =Budgets!AW71 -> 0 | CS10: =CR10-CT10 -> 0 | CT10: =Budgets!AX71 -> 0 | CU10: =CT10-CV10 -> 0 | CV10: =Budgets!AY71 -> 0 | CW10: =CV10-CX10 -> 0 | CX10: =Budgets!AZ71 -> 0 | CY10: =CX10-CZ10 -> 0 | CZ10: =Budgets!BA71 -> 0 | DA10: =CZ10-DB10 -> 0 | DB10: =Budgets!BB71 -> 0 | DC10: =DB10-DD10 -> 0 | DD10: =Budgets!BC71 -> 0 | DE10: =DD10-DF10 -> 0 | DF10: =Budgets!BD71 -> 0 | DG10: =DF10-DH10 -> 0 | DH10: =Budgets!BE71 -> 0 | DI10: =DH10-DJ10 -> 0 | DJ10: =Budgets!BF71 -> 0 | DK10: =DJ10-DL10 -> 0 | DL10: =Budgets!BG71 -> 0 | DM10: =DL10-DN10 -> 0 | DN10: =Budgets!BH71 -> 0 | DO10: =DN10-DP10 -> 0 | DP10: =Budgets!BI71 -> 0 | DQ10: =DP10-DR10 -> 0 | DR10: =Budgets!BJ71 -> 0 | DS10: =DR10-DT10 -> 0 | DT10: =Budgets!BK71 -> 0 | DU10: =DT10-DV10 -> 0 | DV10: =Budgets!BL71 -> 0 | DW10: =DV10-DX10 -> 0 | DX10: =Budgets!BM71 -> 0 | DY10: =DX10-DZ10 -> 0 | DZ10: =Budgets!BN71 -> 0 | EA10: =DZ10-EB10 -> 0 | EB10: =Budgets!BO71 -> 0 | EC10: =EB10-ED10 -> 0 | ED10: =Budgets!BP71 -> 0 | EE10: =ED10-EF10 -> 0 | EF10: =Budgets!BQ71 -> 0 | EG10: =EF10-EH10 -> 0 | EH10: =Budgets!BR71 -> 0 | EI10: =EH10-EJ10 -> 0 | EJ10: =Budgets!BS71 -> 0 | EK10: =EJ10-EL10 -> 0 | EL10: =Budgets!BT71 -> 0 | EM10: =EL10-EN10 -> 0 | EN10: =Budgets!BU71 -> 0 | EO10: =EN10-EP10 -> 0 | EP10: =Budgets!BV71 -> 0 | EQ10: =EP10-ER10 -> 0 | ER10: =Budgets!BW71 -> 0 | ES10: =ER10-ET10 -> 0 | ET10: =Budgets!BX71 -> 0 | EU10: =ET10-EV10 -> 0 | EV10: =Budgets!BY71 -> 0 | EW10: =EV10-EX10 -> 0 | EX10: =Budgets!BZ71 -> 0
A11: Trade Debtors | B11: ='Balance Sheet'!G11 -> 646856.76 | D11: =B11 -> 646856.76 | E11: =D11-F11 -> 383396 | F11: =Budgets!D72 -> 263460.76 | G11: =F11-H11 -> -22120.92 | H11: =Budgets!E72 -> 285581.68 | I11: =H11-J11 -> 166042 | J11: =Budgets!F72 -> 119539.68 | K11: =J11-L11 -> 11536 | L11: =Budgets!G72 -> 108003.68 | M11: =L11-N11 -> -8000 | N11: =Budgets!H72 -> 116003.68 | O11: =N11-P11 -> -26900 | P11: =Budgets!I72 -> 142903.68 | Q11: =P11-R11 -> -27500 | R11: =Budgets!J72 -> 170403.68 | S11: =R11-T11 -> -40000 | T11: =Budgets!K72 -> 210403.68 | U11: =T11-V11 -> -34500 | V11: =Budgets!L72 -> 244903.68 | W11: =V11-X11 -> -80500 | X11: =Budgets!M72 -> 325403.68 | Y11: =X11-Z11 -> -107330 | Z11: =Budgets!N72 -> 432733.68 | AA11: =Z11-AB11 -> 21650 | AB11: =Budgets!O72 -> 411083.68 | AC11: =AB11-AD11 -> -41670 | AD11: =Budgets!P72 -> 452753.68 | AE11: =AD11-AF11 -> -56250 | AF11: =Budgets!Q72 -> 509003.68 | AG11: =AF11-AH11 -> 3000 | AH11: =Budgets!R72 -> 506003.68 | AI11: =AH11-AJ11 -> 78469.212 | AJ11: =Budgets!S72 -> 427534.47 | AK11: =AJ11-AL11 -> 98058.712 | AL11: =Budgets!T72 -> 329475.76 | AM11: =AL11-AN11 -> 27492.5 | AN11: =Budgets!U72 -> 301983.26 | AO11: =AN11-AP11 -> -239313.55 | AP11: =Budgets!V72 -> 541296.8 | AQ11: =AP11-AR11 -> -183320.05 | AR11: =Budgets!W72 -> 724616.85 | AS11: =AR11-AT11 -> 75187 | AT11: =Budgets!X72 -> 649429.85 | AU11: =AT11-AV11 -> -64912.5 | AV11: =Budgets!Y72 -> 714342.35 | AW11: =AV11-AX11 -> -182786.33 | AX11: =Budgets!Z72 -> 897128.68 | AY11: =AX11-AZ11 -> -109458.33 | AZ11: =Budgets!AA72 -> 1006587 | BA11: =AZ11-BB11 -> 1312.5 | BB11: =Budgets!AB72 -> 1005274.5 | BC11: =BB11-BD11 -> -49125 | BD11: =Budgets!AC72 -> 1054399.5 | BE11: =BD11-BF11 -> -184895.83 | BF11: =Budgets!AD72 -> 1239295.3 | BG11: =BF11-BH11 -> -113583.33 | BH11: =Budgets!AE72 -> 1352878.7 | BI11: =BH11-BJ11 -> -5812.5 | BJ11: =Budgets!AF72 -> 1358691.2 | BK11: =BJ11-BL11 -> -272770.83 | BL11: =Budgets!AG72 -> 1631462 | BM11: =BL11-BN11 -> -120000 | BN11: =Budgets!AH72 -> 1751462 | BO11: =BN11-BP11 -> -72500 | BP11: =Budgets!AI72 -> 1823962 | BQ11: =BP11-BR11 -> -124333.33 | BR11: =Budgets!AJ72 -> 1948295.3 | BS11: =BR11-BT11 -> 7250 | BT11: =Budgets!AK72 -> 1941045.3 | BU11: =BT11-BV11 -> -116187.5 | BV11: =Budgets!AL72 -> 2057232.8 | BW11: =BV11-BX11 -> -88562.5 | BX11: =Budgets!AM72 -> 2145795.3 | BY11: =BX11-BZ11 -> -183770.83 | BZ11: =Budgets!AN72 -> 2329566.2 | CA11: =BZ11-CB11 -> -480666.67 | CB11: =Budgets!AO72 -> 2810232.8 | CC11: =CB11-CD11 -> -111562.5 | CD11: =Budgets!AP72 -> 2921795.3 | CE11: =CD11-CF11 -> 121958.33 | CF11: =Budgets!AQ72 -> 2799837 | CG11: =CF11-CH11 -> -351916.67 | CH11: =Budgets!AR72 -> 3151753.7 | CI11: =CH11-CJ11 -> -244145.83 | CJ11: =Budgets!AS72 -> 3395899.5 | CK11: =CJ11-CL11 -> -386354.17 | CL11: =Budgets!AT72 -> 3782253.7 | CM11: =CL11-CN11 -> -297291.67 | CN11: =Budgets!AU72 -> 4079545.3 | CO11: =CN11-CP11 -> 108062.5 | CP11: =Budgets!AV72 -> 3971482.8 | CQ11: =CP11-CR11 -> -132770.83 | CR11: =Budgets!AW72 -> 4104253.7 | CS11: =CR11-CT11 -> -390458.33 | CT11: =Budgets!AX72 -> 4494712 | CU11: =CT11-CV11 -> -195020.83 | CV11: =Budgets!AY72 -> 4689732.8 | CW11: =CV11-CX11 -> -281395.83 | CX11: =Budgets!AZ72 -> 4971128.7 | CY11: =CX11-CZ11 -> -564104.17 | CZ11: =Budgets!BA72 -> 5535232.8 | DA11: =CZ11-DB11 -> -510687.5 | DB11: =Budgets!BB72 -> 6045920.3 | DC11: =DB11-DD11 -> -530708.33 | DD11: =Budgets!BC72 -> 6576628.7 | DE11: =DD11-DF11 -> -238395.83 | DF11: =Budgets!BD72 -> 6815024.5 | DG11: =DF11-DH11 -> -161250 | DH11: =Budgets!BE72 -> 6976274.5 | DI11: =DH11-DJ11 -> -430041.67 | DJ11: =Budgets!BF72 -> 7406316.2 | DK11: =DJ11-DL11 -> -465312.5 | DL11: =Budgets!BG72 -> 7871628.7 | DM11: =DL11-DN11 -> -305604.17 | DN11: =Budgets!BH72 -> 8177232.8 | DO11: =DN11-DP11 -> -353104.17 | DP11: =Budgets!BI72 -> 8530337 | DQ11: =DP11-DR11 -> -599562.5 | DR11: =Budgets!BJ72 -> 9129899.5 | DS11: =DR11-DT11 -> -550375 | DT11: =Budgets!BK72 -> 9680274.5 | DU11: =DT11-DV11 -> -593729.17 | DV11: =Budgets!BL72 -> 10274004 | DW11: =DV11-DX11 -> -738104.17 | DX11: =Budgets!BM72 -> 11012108 | DY11: =DX11-DZ11 -> -640958.33 | DZ11: =Budgets!BN72 -> 11653066 | EA11: =DZ11-EB11 -> -373291.67 | EB11: =Budgets!BO72 -> 12026358 | EC11: =EB11-ED11 -> -302937.5 | ED11: =Budgets!BP72 -> 12329295 | EE11: =ED11-EF11 -> -651541.67 | EF11: =Budgets!BQ72 -> 12980837 | EG11: =EF11-EH11 -> -561291.67 | EH11: =Budgets!BR72 -> 13542129 | EI11: =EH11-EJ11 -> -196833.33 | EJ11: =Budgets!BS72 -> 13738962 | EK11: =EJ11-EL11 -> -351625 | EL11: =Budgets!BT72 -> 14090587 | EM11: =EL11-EN11 -> -790416.67 | EN11: =Budgets!BU72 -> 14881004 | EO11: =EN11-EP11 -> -334229.17 | EP11: =Budgets!BV72 -> 15215233 | EQ11: =EP11-ER11 -> -176645.83 | ER11: =Budgets!BW72 -> 15391879 | ES11: =ER11-ET11 -> -739583.33 | ET11: =Budgets!BX72 -> 16131462 | EU11: =ET11-EV11 -> -60916.667 | EV11: =Budgets!BY72 -> 16192379 | EW11: =EV11-EX11 -> 317312.5 | EX11: =Budgets!BZ72 -> 15875066
A12: Other debtors | B12: ='Balance Sheet'!G12 -> 0 | D12: =B12 -> 0 | E12: =D12-F12 -> -495861.96 | F12: =Budgets!D73 -> 495861.96 | G12: =F12-H12 -> 112786.08 | H12: =Budgets!E73 -> 383075.88 | I12: =H12-J12 -> 256861.68 | J12: =Budgets!F73 -> 126214.2 | K12: =J12-L12 -> 119814.2 | L12: =Budgets!G73 -> 6400 | M12: =L12-N12 -> -6400 | N12: =Budgets!H73 -> 12800 | O12: =N12-P12 -> -6400 | P12: =Budgets!I73 -> 19200 | Q12: =P12-R12 -> -6400 | R12: =Budgets!J73 -> 25600 | S12: =R12-T12 -> -6400 | T12: =Budgets!K73 -> 32000 | U12: =T12-V12 -> -28000 | V12: =Budgets!L73 -> 60000 | W12: =V12-X12 -> 0 | X12: =Budgets!M73 -> 60000 | Y12: =X12-Z12 -> 0 | Z12: =Budgets!N73 -> 60000 | AA12: =Z12-AB12 -> 0 | AB12: =Budgets!O73 -> 60000 | AC12: =AB12-AD12 -> 0 | AD12: =Budgets!P73 -> 60000 | AE12: =AD12-AF12 -> 0 | AF12: =Budgets!Q73 -> 60000 | AG12: =AF12-AH12 -> 0 | AH12: =Budgets!R73 -> 60000 | AI12: =AH12-AJ12 -> -68750 | AJ12: =Budgets!S73 -> 128750 | AK12: =AJ12-AL12 -> -16666.667 | AL12: =Budgets!T73 -> 145416.67 | AM12: =AL12-AN12 -> -14583.333 | AN12: =Budgets!U73 -> 160000 | AO12: =AN12-AP12 -> -183516.67 | AP12: =Budgets!V73 -> 343516.67 | AQ12: =AP12-AR12 -> 25683.333 | AR12: =Budgets!W73 -> 317833.33 | AS12: =AR12-AT12 -> 4083.3333 | AT12: =Budgets!X73 -> 313750 | AU12: =AT12-AV12 -> 9166.6667 | AV12: =Budgets!Y73 -> 304583.33 | AW12: =AV12-AX12 -> 34166.667 | AX12: =Budgets!Z73 -> 270416.67 | AY12: =AX12-AZ12 -> 11250 | AZ12: =Budgets!AA73 -> 259166.67 | BA12: =AZ12-BB12 -> 13333.333 | BB12: =Budgets!AB73 -> 245833.33 | BC12: =BB12-BD12 -> 38333.333 | BD12: =Budgets!AC73 -> 207500 | BE12: =BD12-BF12 -> 38333.333 | BF12: =Budgets!AD73 -> 169166.67 | BG12: =BF12-BH12 -> -32500 | BH12: =Budgets!AE73 -> 201666.67 | BI12: =BH12-BJ12 -> -80416.667 | BJ12: =Budgets!AF73 -> 282083.33 | BK12: =BJ12-BL12 -> -28333.333 | BL12: =Budgets!AG73 -> 310416.67 | BM12: =BL12-BN12 -> -124166.67 | BN12: =Budgets!AH73 -> 434583.33 | BO12: =BN12-BP12 -> -119083.33 | BP12: =Budgets!AI73 -> 553666.67 | BQ12: =BP12-BR12 -> -23000 | BR12: =Budgets!AJ73 -> 576666.67 | BS12: =BR12-BT12 -> -17916.667 | BT12: =Budgets!AK73 -> 594583.33 | BU12: =BT12-BV12 -> -15833.333 | BV12: =Budgets!AL73 -> 610416.67 | BW12: =BV12-BX12 -> -38750 | BX12: =Budgets!AM73 -> 649166.67 | BY12: =BX12-BZ12 -> -146250 | BZ12: =Budgets!AN73 -> 795416.67 | CA12: =BZ12-CB12 -> 39166.667 | CB12: =Budgets!AO73 -> 756250 | CC12: =CB12-CD12 -> 66250 | CD12: =Budgets!AP73 -> 690000 | CE12: =CD12-CF12 -> 16250 | CF12: =Budgets!AQ73 -> 673750 | CG12: =CF12-CH12 -> -168333.33 | CH12: =Budgets!AR73 -> 842083.33 | CI12: =CH12-CJ12 -> 17083.333 | CJ12: =Budgets!AS73 -> 825000 | CK12: =CJ12-CL12 -> -42500 | CL12: =Budgets!AT73 -> 867500 | CM12: =CL12-CN12 -> -37416.667 | CN12: =Budgets!AU73 -> 904916.67 | CO12: =CN12-CP12 -> 56583.333 | CP12: =Budgets!AV73 -> 848333.33 | CQ12: =CP12-CR12 -> 36666.667 | CR12: =Budgets!AW73 -> 811666.67 | CS12: =CR12-CT12 -> 25000 | CT12: =Budgets!AX73 -> 786666.67 | CU12: =CT12-CV12 -> 25000 | CV12: =Budgets!AY73 -> 761666.67 | CW12: =CV12-CX12 -> -75000 | CX12: =Budgets!AZ73 -> 836666.67 | CY12: =CX12-CZ12 -> 100000 | CZ12: =Budgets!BA73 -> 736666.67 | DA12: =CZ12-DB12 -> 125000 | DB12: =Budgets!BB73 -> 611666.67 | DC12: =DB12-DD12 -> 0 | DD12: =Budgets!BC73 -> 611666.67 | DE12: =DD12-DF12 -> -100000 | DF12: =Budgets!BD73 -> 711666.67 | DG12: =DF12-DH12 -> 0 | DH12: =Budgets!BE73 -> 711666.67 | DI12: =DH12-DJ12 -> -25000 | DJ12: =Budgets!BF73 -> 736666.67 | DK12: =DJ12-DL12 -> -97000 | DL12: =Budgets!BG73 -> 833666.67 | DM12: =DL12-DN12 -> 47000 | DN12: =Budgets!BH73 -> 786666.67 | DO12: =DN12-DP12 -> 50000 | DP12: =Budgets!BI73 -> 736666.67 | DQ12: =DP12-DR12 -> 75000 | DR12: =Budgets!BJ73 -> 661666.67 | DS12: =DR12-DT12 -> -25000 | DT12: =Budgets!BK73 -> 686666.67 | DU12: =DT12-DV12 -> -100000 | DV12: =Budgets!BL73 -> 786666.67 | DW12: =DV12-DX12 -> 100000 | DX12: =Budgets!BM73 -> 686666.67 | DY12: =DX12-DZ12 -> 125000 | DZ12: =Budgets!BN73 -> 561666.67 | EA12: =DZ12-EB12 -> 0 | EB12: =Budgets!BO73 -> 561666.67 | EC12: =EB12-ED12 -> -75000 | ED12: =Budgets!BP73 -> 636666.67 | EE12: =ED12-EF12 -> -25000 | EF12: =Budgets!BQ73 -> 661666.67 | EG12: =EF12-EH12 -> -25000 | EH12: =Budgets!BR73 -> 686666.67 | EI12: =EH12-EJ12 -> -50000 | EJ12: =Budgets!BS73 -> 736666.67 | EK12: =EJ12-EL12 -> 25000 | EL12: =Budgets!BT73 -> 711666.67 | EM12: =EL12-EN12 -> 25000 | EN12: =Budgets!BU73 -> 686666.67 | EO12: =EN12-EP12 -> 75000 | EP12: =Budgets!BV73 -> 611666.67 | EQ12: =EP12-ER12 -> -25000 | ER12: =Budgets!BW73 -> 636666.67 | ES12: =ER12-ET12 -> -100000 | ET12: =Budgets!BX73 -> 736666.67 | EU12: =ET12-EV12 -> 100000 | EV12: =Budgets!BY73 -> 636666.67 | EW12: =EV12-EX12 -> 125000 | EX12: =Budgets!BZ73 -> 511666.67
A13: VAT | B13: ='Balance Sheet'!G13 -> 0 | D13: =B13 -> 0 | E13: =D13-F13 -> -38857.632 | F13: =Budgets!D74 -> 38857.632 | G13: =F13-H13 -> -4983.2496 | H13: =Budgets!E74 -> 43840.882 | I13: =H13-J13 -> -4471.8673 | J13: =Budgets!F74 -> 48312.749 | K13: =J13-L13 -> 39538.882 | L13: =Budgets!G74 -> 8773.8673 | M13: =L13-N13 -> -4302 | N13: =Budgets!H74 -> 13075.867 | O13: =N13-P13 -> -4764 | P13: =Budgets!I74 -> 17839.867 | Q13: =P13-R13 -> 9323.8673 | R13: =Budgets!J74 -> 8516 | S13: =R13-T13 -> -3964 | T13: =Budgets!K74 -> 12480 | U13: =T13-V13 -> -3062 | V13: =Budgets!L74 -> 15542 | W13: =V13-X13 -> 11126 | X13: =Budgets!M74 -> 4416 | Y13: =X13-Z13 -> -915.4 | Z13: =Budgets!N74 -> 5331.4 | AA13: =Z13-AB13 -> -3787 | AB13: =Budgets!O74 -> 9118.4 | AC13: =AB13-AD13 -> 1249.4 | AD13: =Budgets!P74 -> 7869 | AE13: =AD13-AF13 -> -662 | AF13: =Budgets!Q74 -> 8531 | AG13: =AF13-AH13 -> -142 | AH13: =Budgets!R74 -> 8673 | AI13: =AH13-AJ13 -> -1373.4842 | AJ13: =Budgets!S74 -> 10046.484 | AK13: =AJ13-AL13 -> -4192.9409 | AL13: =Budgets!T74 -> 14239.425 | AM13: =AL13-AN13 -> -8176.4176 | AN13: =Budgets!U74 -> 22415.843 | AO13: =AN13-AP13 -> 3994.0051 | AP13: =Budgets!V74 -> 18421.838 | AQ13: =AP13-AR13 -> -18043.35 | AR13: =Budgets!W74 -> 36465.188 | AS13: =AR13-AT13 -> -14349.16 | AT13: =Budgets!X74 -> 50814.348 | AU13: =AT13-AV13 -> 28014.671 | AV13: =Budgets!Y74 -> 22799.677 | AW13: =AV13-AX13 -> -5298.85 | AX13: =Budgets!Z74 -> 28098.527 | AY13: =AX13-AZ13 -> -16866.767 | AZ13: =Budgets!AA74 -> 44965.293 | BA13: =AZ13-BB13 -> 16662.593 | BB13: =Budgets!AB74 -> 28302.7 | BC13: =BB13-BD13 -> -6389.6833 | BD13: =Budgets!AC74 -> 34692.383 | BE13: =BD13-BF13 -> -3238.0167 | BF13: =Budgets!AD74 -> 37930.4 | BG13: =BF13-BH13 -> 23554.278 | BH13: =Budgets!AE74 -> 14376.122 | BI13: =BH13-BJ13 -> -5827.2717 | BJ13: =Budgets!AF74 -> 20203.393 | BK13: =BJ13-BL13 -> -14403.522 | BL13: =Budgets!AG74 -> 34606.915 | BM13: =BL13-BN13 -> 14549.872 | BN13: =Budgets!AH74 -> 20057.043 | BO13: =BN13-BP13 -> -2299.7717 | BP13: =Budgets!AI74 -> 22356.815 | BQ13: =BP13-BR13 -> -7927.6883 | BR13: =Budgets!AJ74 -> 30284.503 | BS13: =BR13-BT13 -> 14201.21 | BT13: =Budgets!AK74 -> 16083.293 | BU13: =BT13-BV13 -> -2814.7717 | BV13: =Budgets!AL74 -> 18898.065 | BW13: =BV13-BX13 -> -13525.188 | BX13: =Budgets!AM74 -> 32423.253 | BY13: =BX13-BZ13 -> 11690.377 | BZ13: =Budgets!AN74 -> 20732.877 | CA13: =BZ13-CB13 -> -5878.105 | CB13: =Budgets!AO74 -> 26610.982 | CC13: =CB13-CD13 -> -9161.4383 | CD13: =Budgets!AP74 -> 35772.42 | CE13: =CD13-CF13 -> 15587.076 | CF13: =Budgets!AQ74 -> 20185.344 | CG13: =CF13-CH13 -> -10001.823 | CH13: =Budgets!AR74 -> 30187.167 | CI13: =CH13-CJ13 -> -16190.573 | CJ13: =Budgets!AS74 -> 46377.74 | CK13: =CJ13-CL13 -> 15518.678 | CL13: =Budgets!AT74 -> 30859.062 | CM13: =CL13-CN13 -> -17240.573 | CN13: =Budgets!AU74 -> 48099.635 | CO13: =CN13-CP13 -> -15085.156 | CP13: =Budgets!AV74 -> 63184.791 | CQ13: =CP13-CR13 -> 29647.812 | CR13: =Budgets!AW74 -> 33536.979 | CS13: =CR13-CT13 -> -17718.489 | CT13: =Budgets!AX74 -> 51255.468 | CU13: =CT13-CV13 -> -18558.489 | CV13: =Budgets!AY74 -> 69813.958 | CW13: =CV13-CX13 -> 34742.395 | CX13: =Budgets!AZ74 -> 35071.562 | CY13: =CX13-CZ13 -> -16063.073 | CZ13: =Budgets!BA74 -> 51134.635 | DA13: =CZ13-DB13 -> -14857.656 | DB13: =Budgets!BB74 -> 65992.291 | DC13: =DB13-DD13 -> 34897.825 | DD13: =Budgets!BC74 -> 31094.466 | DE13: =DD13-DF13 -> -15786.81 | DF13: =Budgets!BD74 -> 46881.276 | DG13: =DF13-DH13 -> -16236.81 | DH13: =Budgets!BE74 -> 63118.085 | DI13: =DH13-DJ13 -> 31594.466 | DJ13: =Budgets!BF74 -> 31523.619 | DK13: =DJ13-DL13 -> -13181.393 | DL13: =Budgets!BG74 -> 44705.012 | DM13: =DL13-DN13 -> -13631.393 | DN13: =Budgets!BH74 -> 58336.406 | DO13: =DN13-DP13 -> 32729.036 | DP13: =Budgets!BI74 -> 25607.369 | DQ13: =DP13-DR13 -> -11525.976 | DR13: =Budgets!BJ74 -> 37133.346 | DS13: =DR13-DT13 -> -12125.976 | DT13: =Budgets!BK74 -> 49259.322 | DU13: =DT13-DV13 -> 25057.369 | DV13: =Budgets!BL74 -> 24201.953 | DW13: =DV13-DX13 -> -11625.976 | DX13: =Budgets!BM74 -> 35827.929 | DY13: =DX13-DZ13 -> -12075.976 | DZ13: =Budgets!BN74 -> 47903.906 | EA13: =DZ13-EB13 -> -13025.976 | EB13: =Budgets!BO74 -> 60929.882 | EC13: =EB13-ED13 -> -12575.976 | ED13: =Budgets!BP74 -> 73505.858 | EE13: =ED13-EF13 -> -11718.476 | EF13: =Budgets!BQ74 -> 85224.335 | EG13: =EF13-EH13 -> -11718.476 | EH13: =Budgets!BR74 -> 96942.811 | EI13: =EH13-EJ13 -> -15181.393 | EJ13: =Budgets!BS74 -> 112124.2 | EK13: =EJ13-EL13 -> -13112.643 | EL13: =Budgets!BT74 -> 125236.85 | EM13: =EL13-EN13 -> -13562.643 | EN13: =Budgets!BU74 -> 138799.49 | EO13: =EN13-EP13 -> -16336.81 | EP13: =Budgets!BV74 -> 155136.3 | EQ13: =EP13-ER13 -> -14420.143 | ER13: =Budgets!BW74 -> 169556.44 | ES13: =ER13-ET13 -> -15218.06 | ET13: =Budgets!BX74 -> 184774.5 | EU13: =ET13-EV13 -> -15386.81 | EV13: =Budgets!BY74 -> 200161.31 | EW13: =EV13-EX13 -> -18680.976 | EX13: =Budgets!BZ74 -> 218842.29
A14: Total Current Assets | B14: =SUM(B10:B13) -> 646856.76 | D14: =SUM(D10:D13) -> 646856.76 | F14: =SUM(F10:F13) -> 798180.35 | H14: =SUM(H10:H13) -> 712498.44 | J14: =SUM(J10:J13) -> 294066.63 | L14: =SUM(L10:L13) -> 123177.55 | N14: =SUM(N10:N13) -> 141879.55 | P14: =SUM(P10:P13) -> 179943.55 | R14: =SUM(R10:R13) -> 204519.68 | T14: =SUM(T10:T13) -> 254883.68 | V14: =SUM(V10:V13) -> 320445.68 | X14: =SUM(X10:X13) -> 389819.68 | Z14: =SUM(Z10:Z13) -> 498065.08 | AB14: =SUM(AB10:AB13) -> 480202.08 | AD14: =SUM(AD10:AD13) -> 520622.68 | AF14: =SUM(AF10:AF13) -> 577534.68 | AH14: =SUM(AH10:AH13) -> 574676.68 | AJ14: =SUM(AJ10:AJ13) -> 566330.95 | AL14: =SUM(AL10:AL13) -> 489131.85 | AN14: =SUM(AN10:AN13) -> 484399.1 | AP14: =SUM(AP10:AP13) -> 903235.31 | AR14: =SUM(AR10:AR13) -> 1078915.4 | AT14: =SUM(AT10:AT13) -> 1013994.2 | AV14: =SUM(AV10:AV13) -> 1041725.4 | AX14: =SUM(AX10:AX13) -> 1195643.9 | AZ14: =SUM(AZ10:AZ13) -> 1310719 | BB14: =SUM(BB10:BB13) -> 1279410.5 | BD14: =SUM(BD10:BD13) -> 1296591.9 | BF14: =SUM(BF10:BF13) -> 1446392.4 | BH14: =SUM(BH10:BH13) -> 1568921.5 | BJ14: =SUM(BJ10:BJ13) -> 1660977.9 | BL14: =SUM(BL10:BL13) -> 1976485.6 | BN14: =SUM(BN10:BN13) -> 2206102.4 | BP14: =SUM(BP10:BP13) -> 2399985.5 | BR14: =SUM(BR10:BR13) -> 2555246.5 | BT14: =SUM(BT10:BT13) -> 2551712 | BV14: =SUM(BV10:BV13) -> 2686547.6 | BX14: =SUM(BX10:BX13) -> 2827385.3 | BZ14: =SUM(BZ10:BZ13) -> 3145715.7 | CB14: =SUM(CB10:CB13) -> 3593093.8 | CD14: =SUM(CD10:CD13) -> 3647567.8 | CF14: =SUM(CF10:CF13) -> 3493772.4 | CH14: =SUM(CH10:CH13) -> 4024024.2 | CJ14: =SUM(CJ10:CJ13) -> 4267277.3 | CL14: =SUM(CL10:CL13) -> 4680612.7 | CN14: =SUM(CN10:CN13) -> 5032561.6 | CP14: =SUM(CP10:CP13) -> 4883001 | CR14: =SUM(CR10:CR13) -> 4949457.3 | CT14: =SUM(CT10:CT13) -> 5332634.1 | CV14: =SUM(CV10:CV13) -> 5521213.5 | CX14: =SUM(CX10:CX13) -> 5842866.9 | CZ14: =SUM(CZ10:CZ13) -> 6323034.1 | DB14: =SUM(DB10:DB13) -> 6723579.3 | DD14: =SUM(DD10:DD13) -> 7219389.8 | DF14: =SUM(DF10:DF13) -> 7573572.5 | DH14: =SUM(DH10:DH13) -> 7751059.3 | DJ14: =SUM(DJ10:DJ13) -> 8174506.5 | DL14: =SUM(DL10:DL13) -> 8750000.4 | DN14: =SUM(DN10:DN13) -> 9022235.9 | DP14: =SUM(DP10:DP13) -> 9292611 | DR14: =SUM(DR10:DR13) -> 9828699.5 | DT14: =SUM(DT10:DT13) -> 10416201 | DV14: =SUM(DV10:DV13) -> 11084872 | DX14: =SUM(DX10:DX13) -> 11734602 | DZ14: =SUM(DZ10:DZ13) -> 12262637 | EB14: =SUM(EB10:EB13) -> 12648954 | ED14: =SUM(ED10:ED13) -> 13039468 | EF14: =SUM(EF10:EF13) -> 13727728 | EH14: =SUM(EH10:EH13) -> 14325738 | EJ14: =SUM(EJ10:EJ13) -> 14587753 | EL14: =SUM(EL10:EL13) -> 14927491 | EN14: =SUM(EN10:EN13) -> 15706470 | EP14: =SUM(EP10:EP13) -> 15982036 | ER14: =SUM(ER10:ER13) -> 16198102 | ET14: =SUM(ET10:ET13) -> 17052903 | EV14: =SUM(EV10:EV13) -> 17029207 | EX14: =SUM(EX10:EX13) -> 16605575
A16: Trade Creditors | B16: ='Balance Sheet'!G17 -> -310568.28 | D16: =B16 -> -310568.28 | E16: =D16-F16 -> -265593.47 | F16: =Budgets!D78 -> -44974.808 | G16: =F16-H16 -> 33417.128 | H16: =Budgets!E78 -> -78391.936 | I16: =H16-J16 -> -6061.6829 | J16: =Budgets!F78 -> -72330.253 | K16: =J16-L16 -> -33404.445 | L16: =Budgets!G78 -> -38925.808 | M16: =L16-N16 -> 5304 | N16: =Budgets!H78 -> -44229.808 | O16: =N16-P16 -> 12396 | P16: =Budgets!I78 -> -56625.808 | Q16: =P16-R16 -> 37044 | R16: =Budgets!J78 -> -93669.808 | S16: =R16-T16 -> -50064 | T16: =Budgets!K78 -> -43605.808 | U16: =T16-V16 -> 74112 | V16: =Budgets!L78 -> -117717.81 | W16: =V16-X16 -> -50112 | X16: =Budgets!M78 -> -67605.808 | Y16: =X16-Z16 -> -33600 | Z16: =Budgets!N78 -> -34005.808 | AA16: =Z16-AB16 -> 24060 | AB16: =Budgets!O78 -> -58065.808 | AC16: =AB16-AD16 -> 120 | AD16: =Budgets!P78 -> -58185.808 | AE16: =AD16-AF16 -> -24000 | AF16: =Budgets!Q78 -> -34185.808 | AG16: =AF16-AH16 -> 12000 | AH16: =Budgets!R78 -> -46185.808 | AI16: =AH16-AJ16 -> 114115.8 | AJ16: =Budgets!S78 -> -160301.61 | AK16: =AJ16-AL16 -> -6000 | AL16: =Budgets!T78 -> -154301.61 | AM16: =AL16-AN16 -> -34740 | AN16: =Budgets!U78 -> -119561.61 | AO16: =AN16-AP16 -> 255840 | AP16: =Budgets!V78 -> -375401.61 | AQ16: =AP16-AR16 -> 13680 | AR16: =Budgets!W78 -> -389081.61 | AS16: =AR16-AT16 -> -233340 | AT16: =Budgets!X78 -> -155741.61 | AU16: =AT16-AV16 -> -25680 | AV16: =Budgets!Y78 -> -130061.61 | AW16: =AV16-AX16 -> -33600 | AX16: =Budgets!Z78 -> -96461.608 | AY16: =AX16-AZ16 -> 72000 | AZ16: =Budgets!AA78 -> -168461.61 | BA16: =AZ16-BB16 -> -15480 | BB16: =Budgets!AB78 -> -152981.61 | BC16: =BB16-BD16 -> -54000 | BD16: =Budgets!AC78 -> -98981.608 | BE16: =BD16-BF16 -> -18000 | BF16: =Budgets!AD78 -> -80981.608 | BG16: =BF16-BH16 -> 108658.59 | BH16: =Budgets!AE78 -> -189640.2 | BI16: =BH16-BJ16 -> 123480 | BJ16: =Budgets!AF78 -> -313120.2 | BK16: =BJ16-BL16 -> 84060 | BL16: =Budgets!AG78 -> -397180.2 | BM16: =BL16-BN16 -> -24000 | BN16: =Budgets!AH78 -> -373180.2 | BO16: =BN16-BP16 -> 116400 | BP16: =Budgets!AI78 -> -489580.2 | BQ16: =BP16-BR16 -> -80280 | BR16: =Budgets!AJ78 -> -409300.2 | BS16: =BR16-BT16 -> -128280 | BT16: =Budgets!AK78 -> -281020.2 | BU16: =BT16-BV16 -> -27600 | BV16: =Budgets!AL78 -> -253420.2 | BW16: =BV16-BX16 -> 102000 | BX16: =Budgets!AM78 -> -355420.2 | BY16: =BX16-BZ16 -> 108000 | BZ16: =Budgets!AN78 -> -463420.2 | CA16: =BZ16-CB16 -> -60000 | CB16: =Budgets!AO78 -> -403420.2 | CC16: =CB16-CD16 -> -228000 | CD16: =Budgets!AP78 -> -175420.2 | CE16: =CD16-CF16 -> 34279.519 | CF16: =Budgets!AQ78 -> -209699.72 | CG16: =CF16-CH16 -> 288000 | CH16: =Budgets!AR78 -> -497699.72 | CI16: =CH16-CJ16 -> 54060 | CJ16: =Budgets!AS78 -> -551759.72 | CK16: =CJ16-CL16 -> -144000 | CL16: =Budgets!AT78 -> -407759.72 | CM16: =CL16-CN16 -> 86400 | CN16: =Budgets!AU78 -> -494159.72 | CO16: =CN16-CP16 -> -104400 | CP16: =Budgets!AV78 -> -389759.72 | CQ16: =CP16-CR16 -> -86340 | CR16: =Budgets!AW78 -> -303419.72 | CS16: =CR16-CT16 -> 44400 | CT16: =Budgets!AX78 -> -347819.72 | CU16: =CT16-CV16 -> 42000 | CV16: =Budgets!AY78 -> -389819.72 | CW16: =CV16-CX16 -> 108000 | CX16: =Budgets!AZ78 -> -497819.72 | CY16: =CX16-CZ16 -> -90000 | CZ16: =Budgets!BA78 -> -407819.72 | DA16: =CZ16-DB16 -> -228000 | DB16: =Budgets!BB78 -> -179819.72 | DC16: =DB16-DD16 -> 112430.5 | DD16: =Budgets!BC78 -> -292250.21 | DE16: =DD16-DF16 -> 270000 | DF16: =Budgets!BD78 -> -562250.21 | DG16: =DF16-DH16 -> 12000 | DH16: =Budgets!BE78 -> -574250.21 | DI16: =DH16-DJ16 -> -102000 | DJ16: =Budgets!BF78 -> -472250.21 | DK16: =DJ16-DL16 -> 116400 | DL16: =Budgets!BG78 -> -588650.21 | DM16: =DL16-DN16 -> -74400 | DN16: =Budgets!BH78 -> -514250.21 | DO16: =DN16-DP16 -> -188400 | DP16: =Budgets!BI78 -> -325850.21 | DQ16: =DP16-DR16 -> -33600 | DR16: =Budgets!BJ78 -> -292250.21 | DS16: =DR16-DT16 -> 102000 | DT16: =Budgets!BK78 -> -394250.21 | DU16: =DT16-DV16 -> 198000 | DV16: =Budgets!BL78 -> -592250.21 | DW16: =DV16-DX16 -> -150000 | DX16: =Budgets!BM78 -> -442250.21 | DY16: =DX16-DZ16 -> -258000 | DZ16: =Budgets!BN78 -> -184250.21 | EA16: =DZ16-EB16 -> 120600 | EB16: =Budgets!BO78 -> -304850.21 | EC16: =EB16-ED16 -> 240000 | ED16: =Budgets!BP78 -> -544850.21 | EE16: =ED16-EF16 -> 30000 | EF16: =Budgets!BQ78 -> -574850.21 | EG16: =EF16-EH16 -> -60000 | EH16: =Budgets!BR78 -> -514850.21 | EI16: =EH16-EJ16 -> 30000 | EJ16: =Budgets!BS78 -> -544850.21 | EK16: =EJ16-EL16 -> -60000 | EL16: =Budgets!BT78 -> -484850.21 | EM16: =EL16-EN16 -> -90000 | EN16: =Budgets!BU78 -> -394850.21 | EO16: =EN16-EP16 -> -60000 | EP16: =Budgets!BV78 -> -334850.21 | EQ16: =EP16-ER16 -> 60000 | ER16: =Budgets!BW78 -> -394850.21 | ES16: =ER16-ET16 -> 210000 | ET16: =Budgets!BX78 -> -604850.21 | EU16: =ET16-EV16 -> -150000 | EV16: =Budgets!BY78 -> -454850.21 | EW16: =EV16-EX16 -> -270000 | EX16: =Budgets!BZ78 -> -184850.21
A17: Deferred Revenue | B17: ='Balance Sheet'!G18 -> 0 | D17: =B17 -> 0 | E17: =D17-F17 -> 0 | F17: =Budgets!D79 -> 0 | G17: =F17-H17 -> 0 | H17: =Budgets!E79 -> 0 | I17: =H17-J17 -> 0 | J17: =Budgets!F79 -> 0 | K17: =J17-L17 -> 0 | L17: =Budgets!G79 -> 0 | M17: =L17-N17 -> 0 | N17: =Budgets!H79 -> 0 | O17: =N17-P17 -> 0 | P17: =Budgets!I79 -> 0 | Q17: =P17-R17 -> 0 | R17: =Budgets!J79 -> 0 | S17: =R17-T17 -> 0 | T17: =Budgets!K79 -> 0 | U17: =T17-V17 -> 0 | V17: =Budgets!L79 -> 0 | W17: =V17-X17 -> 0 | X17: =Budgets!M79 -> 0 | Y17: =X17-Z17 -> 0 | Z17: =Budgets!N79 -> 0 | AA17: =Z17-AB17 -> 0 | AB17: =Budgets!O79 -> 0 | AC17: =AB17-AD17 -> 0 | AD17: =Budgets!P79 -> 0 | AE17: =AD17-AF17 -> 0 | AF17: =Budgets!Q79 -> 0 | AG17: =AF17-AH17 -> 0 | AH17: =Budgets!R79 -> 0 | AI17: =AH17-AJ17 -> 0 | AJ17: =Budgets!S79 -> 0 | AK17: =AJ17-AL17 -> 0 | AL17: =Budgets!T79 -> 0 | AM17: =AL17-AN17 -> 0 | AN17: =Budgets!U79 -> 0 | AO17: =AN17-AP17 -> 0 | AP17: =Budgets!V79 -> 0 | AQ17: =AP17-AR17 -> 0 | AR17: =Budgets!W79 -> 0 | AS17: =AR17-AT17 -> 0 | AT17: =Budgets!X79 -> 0 | AU17: =AT17-AV17 -> 0 | AV17: =Budgets!Y79 -> 0 | AW17: =AV17-AX17 -> 0 | AX17: =Budgets!Z79 -> 0 | AY17: =AX17-AZ17 -> 0 | AZ17: =Budgets!AA79 -> 0 | BA17: =AZ17-BB17 -> 0 | BB17: =Budgets!AB79 -> 0 | BC17: =BB17-BD17 -> 0 | BD17: =Budgets!AC79 -> 0 | BE17: =BD17-BF17 -> 0 | BF17: =Budgets!AD79 -> 0 | BG17: =BF17-BH17 -> 0 | BH17: =Budgets!AE79 -> 0 | BI17: =BH17-BJ17 -> 0 | BJ17: =Budgets!AF79 -> 0 | BK17: =BJ17-BL17 -> 0 | BL17: =Budgets!AG79 -> 0 | BM17: =BL17-BN17 -> 0 | BN17: =Budgets!AH79 -> 0 | BO17: =BN17-BP17 -> 0 | BP17: =Budgets!AI79 -> 0 | BQ17: =BP17-BR17 -> 0 | BR17: =Budgets!AJ79 -> 0 | BS17: =BR17-BT17 -> 0 | BT17: =Budgets!AK79 -> 0 | BU17: =BT17-BV17 -> 0 | BV17: =Budgets!AL79 -> 0 | BW17: =BV17-BX17 -> 0 | BX17: =Budgets!AM79 -> 0 | BY17: =BX17-BZ17 -> 0 | BZ17: =Budgets!AN79 -> 0 | CA17: =BZ17-CB17 -> 0 | CB17: =Budgets!AO79 -> 0 | CC17: =CB17-CD17 -> 0 | CD17: =Budgets!AP79 -> 0 | CE17: =CD17-CF17 -> 0 | CF17: =Budgets!AQ79 -> 0 | CG17: =CF17-CH17 -> 0 | CH17: =Budgets!AR79 -> 0 | CI17: =CH17-CJ17 -> 0 | CJ17: =Budgets!AS79 -> 0 | CK17: =CJ17-CL17 -> 0 | CL17: =Budgets!AT79 -> 0 | CM17: =CL17-CN17 -> 0 | CN17: =Budgets!AU79 -> 0 | CO17: =CN17-CP17 -> 0 | CP17: =Budgets!AV79 -> 0 | CQ17: =CP17-CR17 -> 0 | CR17: =Budgets!AW79 -> 0 | CS17: =CR17-CT17 -> 0 | CT17: =Budgets!AX79 -> 0 | CU17: =CT17-CV17 -> 0 | CV17: =Budgets!AY79 -> 0 | CW17: =CV17-CX17 -> 0 | CX17: =Budgets!AZ79 -> 0 | CY17: =CX17-CZ17 -> 0 | CZ17: =Budgets!BA79 -> 0 | DA17: =CZ17-DB17 -> 0 | DB17: =Budgets!BB79 -> 0 | DC17: =DB17-DD17 -> 0 | DD17: =Budgets!BC79 -> 0 | DE17: =DD17-DF17 -> 0 | DF17: =Budgets!BD79 -> 0 | DG17: =DF17-DH17 -> 0 | DH17: =Budgets!BE79 -> 0 | DI17: =DH17-DJ17 -> 0 | DJ17: =Budgets!BF79 -> 0 | DK17: =DJ17-DL17 -> 0 | DL17: =Budgets!BG79 -> 0 | DM17: =DL17-DN17 -> 0 | DN17: =Budgets!BH79 -> 0 | DO17: =DN17-DP17 -> 0 | DP17: =Budgets!BI79 -> 0 | DQ17: =DP17-DR17 -> 0 | DR17: =Budgets!BJ79 -> 0 | DS17: =DR17-DT17 -> 0 | DT17: =Budgets!BK79 -> 0 | DU17: =DT17-DV17 -> 0 | DV17: =Budgets!BL79 -> 0 | DW17: =DV17-DX17 -> 0 | DX17: =Budgets!BM79 -> 0 | DY17: =DX17-DZ17 -> 0 | DZ17: =Budgets!BN79 -> 0 | EA17: =DZ17-EB17 -> 0 | EB17: =Budgets!BO79 -> 0 | EC17: =EB17-ED17 -> 0 | ED17: =Budgets!BP79 -> 0 | EE17: =ED17-EF17 -> 0 | EF17: =Budgets!BQ79 -> 0 | EG17: =EF17-EH17 -> 0 | EH17: =Budgets!BR79 -> 0 | EI17: =EH17-EJ17 -> 0 | EJ17: =Budgets!BS79 -> 0 | EK17: =EJ17-EL17 -> 0 | EL17: =Budgets!BT79 -> 0 | EM17: =EL17-EN17 -> 0 | EN17: =Budgets!BU79 -> 0 | EO17: =EN17-EP17 -> 0 | EP17: =Budgets!BV79 -> 0 | EQ17: =EP17-ER17 -> 0 | ER17: =Budgets!BW79 -> 0 | ES17: =ER17-ET17 -> 0 | ET17: =Budgets!BX79 -> 0 | EU17: =ET17-EV17 -> 0 | EV17: =Budgets!BY79 -> 0 | EW17: =EV17-EX17 -> 0 | EX17: =Budgets!BZ79 -> 0
A18: Other creditors | B18: ='Balance Sheet'!G19 -> 0 | D18: =B18 -> 0 | E18: =D18-F18 -> 372248.63 | F18: =Budgets!D80 -> -372248.63 | G18: =F18-H18 -> 4983.2496 | H18: =Budgets!E80 -> -377231.88 | I18: =H18-J18 -> 4471.8673 | J18: =Budgets!F80 -> -381703.75 | K18: =J18-L18 -> -339538.88 | L18: =Budgets!G80 -> -42164.867 | M18: =L18-N18 -> 104302 | N18: =Budgets!H80 -> -146466.87 | O18: =N18-P18 -> 104764 | P18: =Budgets!I80 -> -251230.87 | Q18: =P18-R18 -> 196676.13 | R18: =Budgets!J80 -> -447907 | S18: =R18-T18 -> 3964 | T18: =Budgets!K80 -> -451871 | U18: =T18-V18 -> 3062 | V18: =Budgets!L80 -> -454933 | W18: =V18-X18 -> -28292.667 | X18: =Budgets!M80 -> -426640.33 | Y18: =X18-Z18 -> -16251.267 | Z18: =Budgets!N80 -> -410389.07 | AA18: =Z18-AB18 -> -67879.667 | AB18: =Budgets!O80 -> -342509.4 | AC18: =AB18-AD18 -> -1249.4 | AD18: =Budgets!P80 -> -341260 | AE18: =AD18-AF18 -> 662 | AF18: =Budgets!Q80 -> -341922 | AG18: =AF18-AH18 -> 142 | AH18: =Budgets!R80 -> -342064 | AI18: =AH18-AJ18 -> 1373.4842 | AJ18: =Budgets!S80 -> -343437.48 | AK18: =AJ18-AL18 -> 4192.9409 | AL18: =Budgets!T80 -> -347630.43 | AM18: =AL18-AN18 -> 8176.4176 | AN18: =Budgets!U80 -> -355806.84 | AO18: =AN18-AP18 -> -3994.0051 | AP18: =Budgets!V80 -> -351812.84 | AQ18: =AP18-AR18 -> 18043.35 | AR18: =Budgets!W80 -> -369856.19 | AS18: =AR18-AT18 -> 14349.16 | AT18: =Budgets!X80 -> -384205.35 | AU18: =AT18-AV18 -> -28014.671 | AV18: =Budgets!Y80 -> -356190.68 | AW18: =AV18-AX18 -> 5298.85 | AX18: =Budgets!Z80 -> -361489.53 | AY18: =AX18-AZ18 -> 16866.767 | AZ18: =Budgets!AA80 -> -378356.29 | BA18: =AZ18-BB18 -> -16662.593 | BB18: =Budgets!AB80 -> -361693.7 | BC18: =BB18-BD18 -> 6389.6833 | BD18: =Budgets!AC80 -> -368083.38 | BE18: =BD18-BF18 -> 3238.0167 | BF18: =Budgets!AD80 -> -371321.4 | BG18: =BF18-BH18 -> -23554.278 | BH18: =Budgets!AE80 -> -347767.12 | BI18: =BH18-BJ18 -> 5827.2717 | BJ18: =Budgets!AF80 -> -353594.39 | BK18: =BJ18-BL18 -> 14403.522 | BL18: =Budgets!AG80 -> -367997.92 | BM18: =BL18-BN18 -> -14549.872 | BN18: =Budgets!AH80 -> -353448.04 | BO18: =BN18-BP18 -> 2299.7717 | BP18: =Budgets!AI80 -> -355747.82 | BQ18: =BP18-BR18 -> 7927.6883 | BR18: =Budgets!AJ80 -> -363675.5 | BS18: =BR18-BT18 -> -14201.21 | BT18: =Budgets!AK80 -> -349474.29 | BU18: =BT18-BV18 -> 2814.7717 | BV18: =Budgets!AL80 -> -352289.07 | BW18: =BV18-BX18 -> 13525.188 | BX18: =Budgets!AM80 -> -365814.25 | BY18: =BX18-BZ18 -> -11690.377 | BZ18: =Budgets!AN80 -> -354123.88 | CA18: =BZ18-CB18 -> 5878.105 | CB18: =Budgets!AO80 -> -360001.98 | CC18: =CB18-CD18 -> 9161.4383 | CD18: =Budgets!AP80 -> -369163.42 | CE18: =CD18-CF18 -> -15587.076 | CF18: =Budgets!AQ80 -> -353576.34 | CG18: =CF18-CH18 -> 10001.823 | CH18: =Budgets!AR80 -> -363578.17 | CI18: =CH18-CJ18 -> 16190.573 | CJ18: =Budgets!AS80 -> -379768.74 | CK18: =CJ18-CL18 -> -15518.678 | CL18: =Budgets!AT80 -> -364250.06 | CM18: =CL18-CN18 -> 17240.573 | CN18: =Budgets!AU80 -> -381490.63 | CO18: =CN18-CP18 -> 15085.156 | CP18: =Budgets!AV80 -> -396575.79 | CQ18: =CP18-CR18 -> -29647.812 | CR18: =Budgets!AW80 -> -366927.98 | CS18: =CR18-CT18 -> 17718.489 | CT18: =Budgets!AX80 -> -384646.47 | CU18: =CT18-CV18 -> 18558.489 | CV18: =Budgets!AY80 -> -403204.96 | CW18: =CV18-CX18 -> -34742.395 | CX18: =Budgets!AZ80 -> -368462.56 | CY18: =CX18-CZ18 -> 16063.073 | CZ18: =Budgets!BA80 -> -384525.63 | DA18: =CZ18-DB18 -> 14857.656 | DB18: =Budgets!BB80 -> -399383.29 | DC18: =DB18-DD18 -> -34897.825 | DD18: =Budgets!BC80 -> -364485.47 | DE18: =DD18-DF18 -> 15786.81 | DF18: =Budgets!BD80 -> -380272.28 | DG18: =DF18-DH18 -> 16236.81 | DH18: =Budgets!BE80 -> -396509.09 | DI18: =DH18-DJ18 -> -31594.466 | DJ18: =Budgets!BF80 -> -364914.62 | DK18: =DJ18-DL18 -> 13181.393 | DL18: =Budgets!BG80 -> -378096.01 | DM18: =DL18-DN18 -> 13631.393 | DN18: =Budgets!BH80 -> -391727.41 | DO18: =DN18-DP18 -> -32729.036 | DP18: =Budgets!BI80 -> -358998.37 | DQ18: =DP18-DR18 -> 11525.976 | DR18: =Budgets!BJ80 -> -370524.35 | DS18: =DR18-DT18 -> 12125.976 | DT18: =Budgets!BK80 -> -382650.32 | DU18: =DT18-DV18 -> -25057.369 | DV18: =Budgets!BL80 -> -357592.95 | DW18: =DV18-DX18 -> 11625.976 | DX18: =Budgets!BM80 -> -369218.93 | DY18: =DX18-DZ18 -> 12075.976 | DZ18: =Budgets!BN80 -> -381294.91 | EA18: =DZ18-EB18 -> 13025.976 | EB18: =Budgets!BO80 -> -394320.88 | EC18: =EB18-ED18 -> 12575.976 | ED18: =Budgets!BP80 -> -406896.86 | EE18: =ED18-EF18 -> 11718.476 | EF18: =Budgets!BQ80 -> -418615.33 | EG18: =EF18-EH18 -> 11718.476 | EH18: =Budgets!BR80 -> -430333.81 | EI18: =EH18-EJ18 -> 15181.393 | EJ18: =Budgets!BS80 -> -445515.2 | EK18: =EJ18-EL18 -> 13112.643 | EL18: =Budgets!BT80 -> -458627.85 | EM18: =EL18-EN18 -> 13562.643 | EN18: =Budgets!BU80 -> -472190.49 | EO18: =EN18-EP18 -> 16336.81 | EP18: =Budgets!BV80 -> -488527.3 | EQ18: =EP18-ER18 -> 14420.143 | ER18: =Budgets!BW80 -> -502947.44 | ES18: =ER18-ET18 -> 15218.06 | ET18: =Budgets!BX80 -> -518165.5 | EU18: =ET18-EV18 -> 15386.81 | EV18: =Budgets!BY80 -> -533552.31 | EW18: =EV18-EX18 -> 18680.976 | EX18: =Budgets!BZ80 -> -552233.29
A19: Total Current Liabilities | B19: =SUM(B16:B18) -> -310568.28 | D19: =SUM(D16:D18) -> -310568.28 | F19: =SUM(F16:F18) -> -417223.44 | H19: =SUM(H16:H18) -> -455623.82 | J19: =SUM(J16:J18) -> -454034 | L19: =SUM(L16:L18) -> -81090.675 | N19: =SUM(N16:N18) -> -190696.68 | P19: =SUM(P16:P18) -> -307856.68 | R19: =SUM(R16:R18) -> -541576.81 | T19: =SUM(T16:T18) -> -495476.81 | V19: =SUM(V16:V18) -> -572650.81 | X19: =SUM(X16:X18) -> -494246.14 | Z19: =SUM(Z16:Z18) -> -444394.87 | AB19: =SUM(AB16:AB18) -> -400575.21 | AD19: =SUM(AD16:AD18) -> -399445.81 | AF19: =SUM(AF16:AF18) -> -376107.81 | AH19: =SUM(AH16:AH18) -> -388249.81 | AJ19: =SUM(AJ16:AJ18) -> -503739.09 | AL19: =SUM(AL16:AL18) -> -501932.03 | AN19: =SUM(AN16:AN18) -> -475368.45 | AP19: =SUM(AP16:AP18) -> -727214.45 | AR19: =SUM(AR16:AR18) -> -758937.8 | AT19: =SUM(AT16:AT18) -> -539946.96 | AV19: =SUM(AV16:AV18) -> -486252.28 | AX19: =SUM(AX16:AX18) -> -457951.13 | AZ19: =SUM(AZ16:AZ18) -> -546817.9 | BB19: =SUM(BB16:BB18) -> -514675.31 | BD19: =SUM(BD16:BD18) -> -467064.99 | BF19: =SUM(BF16:BF18) -> -452303.01 | BH19: =SUM(BH16:BH18) -> -537407.32 | BJ19: =SUM(BJ16:BJ18) -> -666714.59 | BL19: =SUM(BL16:BL18) -> -765178.11 | BN19: =SUM(BN16:BN18) -> -726628.24 | BP19: =SUM(BP16:BP18) -> -845328.01 | BR19: =SUM(BR16:BR18) -> -772975.7 | BT19: =SUM(BT16:BT18) -> -630494.49 | BV19: =SUM(BV16:BV18) -> -605709.26 | BX19: =SUM(BX16:BX18) -> -721234.45 | BZ19: =SUM(BZ16:BZ18) -> -817544.07 | CB19: =SUM(CB16:CB18) -> -763422.18 | CD19: =SUM(CD16:CD18) -> -544583.62 | CF19: =SUM(CF16:CF18) -> -563276.06 | CH19: =SUM(CH16:CH18) -> -861277.88 | CJ19: =SUM(CJ16:CJ18) -> -931528.46 | CL19: =SUM(CL16:CL18) -> -772009.78 | CN19: =SUM(CN16:CN18) -> -875650.35 | CP19: =SUM(CP16:CP18) -> -786335.51 | CR19: =SUM(CR16:CR18) -> -670347.7 | CT19: =SUM(CT16:CT18) -> -732466.19 | CV19: =SUM(CV16:CV18) -> -793024.68 | CX19: =SUM(CX16:CX18) -> -866282.28 | CZ19: =SUM(CZ16:CZ18) -> -792345.35 | DB19: =SUM(DB16:DB18) -> -579203.01 | DD19: =SUM(DD16:DD18) -> -656735.68 | DF19: =SUM(DF16:DF18) -> -942522.49 | DH19: =SUM(DH16:DH18) -> -970759.3 | DJ19: =SUM(DJ16:DJ18) -> -837164.83 | DL19: =SUM(DL16:DL18) -> -966746.23 | DN19: =SUM(DN16:DN18) -> -905977.62 | DP19: =SUM(DP16:DP18) -> -684848.58 | DR19: =SUM(DR16:DR18) -> -662774.56 | DT19: =SUM(DT16:DT18) -> -776900.54 | DV19: =SUM(DV16:DV18) -> -949843.17 | DX19: =SUM(DX16:DX18) -> -811469.14 | DZ19: =SUM(DZ16:DZ18) -> -565545.12 | EB19: =SUM(EB16:EB18) -> -699171.09 | ED19: =SUM(ED16:ED18) -> -951747.07 | EF19: =SUM(EF16:EF18) -> -993465.55 | EH19: =SUM(EH16:EH18) -> -945184.02 | EJ19: =SUM(EJ16:EJ18) -> -990365.42 | EL19: =SUM(EL16:EL18) -> -943478.06 | EN19: =SUM(EN16:EN18) -> -867040.7 | EP19: =SUM(EP16:EP18) -> -823377.51 | ER19: =SUM(ER16:ER18) -> -897797.66 | ET19: =SUM(ET16:ET18) -> -1123015.7 | EV19: =SUM(EV16:EV18) -> -988402.53 | EX19: =SUM(EX16:EX18) -> -737083.5
